Workbook

Sheet Configurações
A1: ⚙ CONFIGURAÇÕES GERAIS — PAINEL DE ACOMPANHAMENTO DE ASSESSORES
A2: Preencha o ano, o nome dos 13 assessores, a meta mensal e o saldo pulso inicial (opcional). Todo o restante — dias do mês, totais, ranking, saldos e gráficos — é calculado automaticamente nas 12 abas mensais.
A3: Ano de Referência | B3: 2026
A6: Nº | B6: Nome do Assessor | C6: Meta Mensal de Produção (R$) | D6: Saldo Pulso Inicial (R$)
A7: 1
A8: 2
A9: 3
A10: 4
A11: 5
A12: 6
A13: 7
A14: 8
A15: 9
A16: 10
A17: 11
A18: 12
A19: 13
A21: 🔒 As células em branco com borda azul são as únicas editáveis. O restante da planilha é protegido contra alterações acidentais.
A22: ℹ O Saldo Pulso Inicial é usado apenas como Saldo Anterior do dia 1 de Janeiro. Nos demais meses, o Saldo Anterior do dia 1 puxa automaticamente o último Saldo Pulso do mês anterior.

Sheet Janeiro
A1: ="ACOMPANHAMENTO DIÁRIO DE ASSESSORES — JANEIRO / "&Configurações!$B$3 | KC1: Dia | KD1: Data | KE1: Produção do Dia | KF1: Captação do Dia
A2: ="Dias no mês: "&$Z$3&" | Cada assessor ocupa 1 linha. Role para a direita para ver os dias. Apenas as células destacadas em amarelo são editáveis." | KC2: 1 | KD2: =IF(1<=$Z$3,DATE(Configurações!$B$3,1,1),"") | KE2: =SUM($I$67:$I$79) | KF2: =SUM($D$67:$D$79) | KH2: COE | KI2: =SUM($E$67:$E$79)+SUM($N$67:$N$79)+SUM($W$67:$W$79)+SUM($AF$67:$AF$79)+SUM($AO$67:$AO$79)+SUM($AX$67:$AX$79)+SUM($BG$67:$BG$79)+SUM($BP$67:$BP$79)+SUM($BY$67:$BY$79)+SUM($CH$67:$CH$79)+SUM($CQ$67:$CQ$79)+SUM($CZ$67:$CZ$79)+SUM($DI$67:$DI$79)+SUM($DR$67:$DR$79)+SUM($EA$67:$EA$79)+SUM($EJ$67:$EJ$79)+SUM($ES$67:$ES$79)+SUM($FB$67:$FB$79)+SUM($FK$67:$FK$79)+SUM($FT$67:$FT$79)+SUM($GC$67:$GC$79)+SUM($GL$67:$GL$79)+SUM($GU$67:$GU$79)+SUM($HD$67:$HD$79)+SUM($HM$67:$HM$79)+SUM($HV$67:$HV$79)+SUM($IE$67:$IE$79)+SUM($IN$67:$IN$79)+SUM($IW$67:$IW$79)+SUM($JF$67:$JF$79)+SUM($JO$67:$JO$79)
Y3: Dias no mês | Z3: =DAY(EOMONTH(DATE(Configurações!$B$3,1,1),0)) | KC3: 2 | KD3: =IF(2<=$Z$3,DATE(Configurações!$B$3,1,2),"") | KE3: =SUM($R$67:$R$79) | KF3: =SUM($M$67:$M$79) | KH3: PREVIDÊNCIA | KI3: =SUM($F$67:$F$79)+SUM($O$67:$O$79)+SUM($X$67:$X$79)+SUM($AG$67:$AG$79)+SUM($AP$67:$AP$79)+SUM($AY$67:$AY$79)+SUM($BH$67:$BH$79)+SUM($BQ$67:$BQ$79)+SUM($BZ$67:$BZ$79)+SUM($CI$67:$CI$79)+SUM($CR$67:$CR$79)+SUM($DA$67:$DA$79)+SUM($DJ$67:$DJ$79)+SUM($DS$67:$DS$79)+SUM($EB$67:$EB$79)+SUM($EK$67:$EK$79)+SUM($ET$67:$ET$79)+SUM($FC$67:$FC$79)+SUM($FL$67:$FL$79)+SUM($FU$67:$FU$79)+SUM($GD$67:$GD$79)+SUM($GM$67:$GM$79)+SUM($GV$67:$GV$79)+SUM($HE$67:$HE$79)+SUM($HN$67:$HN$79)+SUM($HW$67:$HW$79)+SUM($IF$67:$IF$79)+SUM($IO$67:$IO$79)+SUM($IX$67:$IX$79)+SUM($JG$67:$JG$79)+SUM($JP$67:$JP$79)
A4: 📊 INDICADORES DO MÊS | KC4: 3 | KD4: =IF(3<=$Z$3,DATE(Configurações!$B$3,1,3),"") | KE4: =SUM($AA$67:$AA$79) | KF4: =SUM($V$67:$V$79) | KH4: CRÉDITO PRIVADO | KI4: =SUM($G$67:$G$79)+SUM($P$67:$P$79)+SUM($Y$67:$Y$79)+SUM($AH$67:$AH$79)+SUM($AQ$67:$AQ$79)+SUM($AZ$67:$AZ$79)+SUM($BI$67:$BI$79)+SUM($BR$67:$BR$79)+SUM($CA$67:$CA$79)+SUM($CJ$67:$CJ$79)+SUM($CS$67:$CS$79)+SUM($DB$67:$DB$79)+SUM($DK$67:$DK$79)+SUM($DT$67:$DT$79)+SUM($EC$67:$EC$79)+SUM($EL$67:$EL$79)+SUM($EU$67:$EU$79)+SUM($FD$67:$FD$79)+SUM($FM$67:$FM$79)+SUM($FV$67:$FV$79)+SUM($GE$67:$GE$79)+SUM($GN$67:$GN$79)+SUM($GW$67:$GW$79)+SUM($HF$67:$HF$79)+SUM($HO$67:$HO$79)+SUM($HX$67:$HX$79)+SUM($IG$67:$IG$79)+SUM($IP$67:$IP$79)+SUM($IY$67:$IY$79)+SUM($JH$67:$JH$79)+SUM($JQ$67:$JQ$79)
A5: PRODUÇÃO TOTAL DO MÊS | C5: CAPTAÇÃO LÍQUIDA DO MÊS | E5: SALDO PULSO TOTAL (ATUAL) | G5: MÉDIA DIÁRIA DA EQUIPE | I5: MELHOR DIA DE PRODUÇÃO | K5: MELHOR ASSESSOR DO MÊS | KC5: 4 | KD5: =IF(4<=$Z$3,DATE(Configurações!$B$3,1,4),"") | KE5: =SUM($AJ$67:$AJ$79) | KF5: =SUM($AE$67:$AE$79) | KH5: TÍTULOS PÚBLICOS | KI5: =SUM($H$67:$H$79)+SUM($Q$67:$Q$79)+SUM($Z$67:$Z$79)+SUM($AI$67:$AI$79)+SUM($AR$67:$AR$79)+SUM($BA$67:$BA$79)+SUM($BJ$67:$BJ$79)+SUM($BS$67:$BS$79)+SUM($CB$67:$CB$79)+SUM($CK$67:$CK$79)+SUM($CT$67:$CT$79)+SUM($DC$67:$DC$79)+SUM($DL$67:$DL$79)+SUM($DU$67:$DU$79)+SUM($ED$67:$ED$79)+SUM($EM$67:$EM$79)+SUM($EV$67:$EV$79)+SUM($FE$67:$FE$79)+SUM($FN$67:$FN$79)+SUM($FW$67:$FW$79)+SUM($GF$67:$GF$79)+SUM($GO$67:$GO$79)+SUM($GX$67:$GX$79)+SUM($HG$67:$HG$79)+SUM($HP$67:$HP$79)+SUM($HY$67:$HY$79)+SUM($IH$67:$IH$79)+SUM($IQ$67:$IQ$79)+SUM($IZ$67:$IZ$79)+SUM($JI$67:$JI$79)+SUM($JR$67:$JR$79)
A6: =SUM($JU$67:$JU$79) | C6: =SUM($JV$67:$JV$79) | E6: =SUM($JW$67:$JW$79) | G6: =IFERROR(SUM($JU$67:$JU$79)/$Z$3,0) | I6: =IFERROR("Dia "&TEXT(INDEX($KD$2:$KD$32,MATCH(MAX($KE$2:$KE$32),$KE$2:$KE$32,0)),"dd/mm")&" - "&TEXT(MAX($KE$2:$KE$32),"R$ #,##0"),"—") | K6: =IFERROR($B$14&" - "&TEXT($C$14,"R$ #,##0"),"—") | KC6: 5 | KD6: =IF(5<=$Z$3,DATE(Configurações!$B$3,1,5),"") | KE6: =SUM($AS$67:$AS$79) | KF6: =SUM($AN$67:$AN$79)
KC7: 6 | KD7: =IF(6<=$Z$3,DATE(Configurações!$B$3,1,6),"") | KE7: =SUM($BB$67:$BB$79) | KF7: =SUM($AW$67:$AW$79)
A8: 💰 TOTAIS POR PRODUTO | KC8: 7 | KD8: =IF(7<=$Z$3,DATE(Configurações!$B$3,1,7),"") | KE8: =SUM($BK$67:$BK$79) | KF8: =SUM($BF$67:$BF$79)
A9: COE | D9: PREVIDÊNCIA | G9: CRÉDITO PRIVADO | J9: TÍTULOS PÚBLICOS | KC9: 8 | KD9: =IF(8<=$Z$3,DATE(Configurações!$B$3,1,8),"") | KE9: =SUM($BT$67:$BT$79) | KF9: =SUM($BO$67:$BO$79)
A10: =SUM($E$67:$E$79)+SUM($N$67:$N$79)+SUM($W$67:$W$79)+SUM($AF$67:$AF$79)+SUM($AO$67:$AO$79)+SUM($AX$67:$AX$79)+SUM($BG$67:$BG$79)+SUM($BP$67:$BP$79)+SUM($BY$67:$BY$79)+SUM($CH$67:$CH$79)+SUM($CQ$67:$CQ$79)+SUM($CZ$67:$CZ$79)+SUM($DI$67:$DI$79)+SUM($DR$67:$DR$79)+SUM($EA$67:$EA$79)+SUM($EJ$67:$EJ$79)+SUM($ES$67:$ES$79)+SUM($FB$67:$FB$79)+SUM($FK$67:$FK$79)+SUM($FT$67:$FT$79)+SUM($GC$67:$GC$79)+SUM($GL$67:$GL$79)+SUM($GU$67:$GU$79)+SUM($HD$67:$HD$79)+SUM($HM$67:$HM$79)+SUM($HV$67:$HV$79)+SUM($IE$67:$IE$79)+SUM($IN$67:$IN$79)+SUM($IW$67:$IW$79)+SUM($JF$67:$JF$79)+SUM($JO$67:$JO$79) | D10: =SUM($F$67:$F$79)+SUM($O$67:$O$79)+SUM($X$67:$X$79)+SUM($AG$67:$AG$79)+SUM($AP$67:$AP$79)+SUM($AY$67:$AY$79)+SUM($BH$67:$BH$79)+SUM($BQ$67:$BQ$79)+SUM($BZ$67:$BZ$79)+SUM($CI$67:$CI$79)+SUM($CR$67:$CR$79)+SUM($DA$67:$DA$79)+SUM($DJ$67:$DJ$79)+SUM($DS$67:$DS$79)+SUM($EB$67:$EB$79)+SUM($EK$67:$EK$79)+SUM($ET$67:$ET$79)+SUM($FC$67:$FC$79)+SUM($FL$67:$FL$79)+SUM($FU$67:$FU$79)+SUM($GD$67:$GD$79)+SUM($GM$67:$GM$79)+SUM($GV$67:$GV$79)+SUM($HE$67:$HE$79)+SUM($HN$67:$HN$79)+SUM($HW$67:$HW$79)+SUM($IF$67:$IF$79)+SUM($IO$67:$IO$79)+SUM($IX$67:$IX$79)+SUM($JG$67:$JG$79)+SUM($JP$67:$JP$79) | G10: =SUM($G$67:$G$79)+SUM($P$67:$P$79)+SUM($Y$67:$Y$79)+SUM($AH$67:$AH$79)+SUM($AQ$67:$AQ$79)+SUM($AZ$67:$AZ$79)+SUM($BI$67:$BI$79)+SUM($BR$67:$BR$79)+SUM($CA$67:$CA$79)+SUM($CJ$67:$CJ$79)+SUM($CS$67:$CS$79)+SUM($DB$67:$DB$79)+SUM($DK$67:$DK$79)+SUM($DT$67:$DT$79)+SUM($EC$67:$EC$79)+SUM($EL$67:$EL$79)+SUM($EU$67:$EU$79)+SUM($FD$67:$FD$79)+SUM($FM$67:$FM$79)+SUM($FV$67:$FV$79)+SUM($GE$67:$GE$79)+SUM($GN$67:$GN$79)+SUM($GW$67:$GW$79)+SUM($HF$67:$HF$79)+SUM($HO$67:$HO$79)+SUM($HX$67:$HX$79)+SUM($IG$67:$IG$79)+SUM($IP$67:$IP$79)+SUM($IY$67:$IY$79)+SUM($JH$67:$JH$79)+SUM($JQ$67:$JQ$79) | J10: =SUM($H$67:$H$79)+SUM($Q$67:$Q$79)+SUM($Z$67:$Z$79)+SUM($AI$67:$AI$79)+SUM($AR$67:$AR$79)+SUM($BA$67:$BA$79)+SUM($BJ$67:$BJ$79)+SUM($BS$67:$BS$79)+SUM($CB$67:$CB$79)+SUM($CK$67:$CK$79)+SUM($CT$67:$CT$79)+SUM($DC$67:$DC$79)+SUM($DL$67:$DL$79)+SUM($DU$67:$DU$79)+SUM($ED$67:$ED$79)+SUM($EM$67:$EM$79)+SUM($EV$67:$EV$79)+SUM($FE$67:$FE$79)+SUM($FN$67:$FN$79)+SUM($FW$67:$FW$79)+SUM($GF$67:$GF$79)+SUM($GO$67:$GO$79)+SUM($GX$67:$GX$79)+SUM($HG$67:$HG$79)+SUM($HP$67:$HP$79)+SUM($HY$67:$HY$79)+SUM($IH$67:$IH$79)+SUM($IQ$67:$IQ$79)+SUM($IZ$67:$IZ$79)+SUM($JI$67:$JI$79)+SUM($JR$67:$JR$79) | KC10: 9 | KD10: =IF(9<=$Z$3,DATE(Configurações!$B$3,1,9),"") | KE10: =SUM($CC$67:$CC$79) | KF10: =SUM($BX$67:$BX$79)
KC11: 10 | KD11: =IF(10<=$Z$3,DATE(Configurações!$B$3,1,10),"") | KE11: =SUM($CL$67:$CL$79) | KF11: =SUM($CG$67:$CG$79)
A12: 🏆 RANKING DE ASSESSORES (TOP 5 EM DESTAQUE) | KC12: 11 | KD12: =IF(11<=$Z$3,DATE(Configurações!$B$3,1,11),"") | KE12: =SUM($CU$67:$CU$79) | KF12: =SUM($CP$67:$CP$79)
A13: Pos. | B13: Assessor | C13: Produção Total | D13: Captação Líquida | E13: Saldo Pulso Atual | F13: Média Diária | G13: Meta Mensal | H13: Status | KC13: 12 | KD13: =IF(12<=$Z$3,DATE(Configurações!$B$3,1,12),"") | KE13: =SUM($DD$67:$DD$79) | KF13: =SUM($CY$67:$CY$79)
A14: 1 | B14: =INDEX($A$67:$A$79,MATCH(LARGE($KA$67:$KA$79,1),$KA$67:$KA$79,0)) | C14: =INDEX($JU$67:$JU$79,MATCH(LARGE($KA$67:$KA$79,1),$KA$67:$KA$79,0)) | D14: =INDEX($JV$67:$JV$79,MATCH(LARGE($KA$67:$KA$79,1),$KA$67:$KA$79,0)) | E14: =INDEX($JW$67:$JW$79,MATCH(LARGE($KA$67:$KA$79,1),$KA$67:$KA$79,0)) | F14: =INDEX($JX$67:$JX$79,MATCH(LARGE($KA$67:$KA$79,1),$KA$67:$KA$79,0)) | G14: =INDEX($JY$67:$JY$79,MATCH(LARGE($KA$67:$KA$79,1),$KA$67:$KA$79,0)) | H14: =IF(G14=0,"— Sem meta",IF(C14>=G14,"✓ Meta atingida","Em andamento")) | KC14: 13 | KD14: =IF(13<=$Z$3,DATE(Configurações!$B$3,1,13),"") | KE14: =SUM($DM$67:$DM$79) | KF14: =SUM($DH$67:$DH$79)
A15: 2 | B15: =INDEX($A$67:$A$79,MATCH(LARGE($KA$67:$KA$79,2),$KA$67:$KA$79,0)) | C15: =INDEX($JU$67:$JU$79,MATCH(LARGE($KA$67:$KA$79,2),$KA$67:$KA$79,0)) | D15: =INDEX($JV$67:$JV$79,MATCH(LARGE($KA$67:$KA$79,2),$KA$67:$KA$79,0)) | E15: =INDEX($JW$67:$JW$79,MATCH(LARGE($KA$67:$KA$79,2),$KA$67:$KA$79,0)) | F15: =INDEX($JX$67:$JX$79,MATCH(LARGE($KA$67:$KA$79,2),$KA$67:$KA$79,0)) | G15: =INDEX($JY$67:$JY$79,MATCH(LARGE($KA$67:$KA$79,2),$KA$67:$KA$79,0)) | H15: =IF(G15=0,"— Sem meta",IF(C15>=G15,"✓ Meta atingida","Em andamento")) | KC15: 14 | KD15: =IF(14<=$Z$3,DATE(Configurações!$B$3,1,14),"") | KE15: =SUM($DV$67:$DV$79) | KF15: =SUM($DQ$67:$DQ$79)
A16: 3 | B16: =INDEX($A$67:$A$79,MATCH(LARGE($KA$67:$KA$79,3),$KA$67:$KA$79,0)) | C16: =INDEX($JU$67:$JU$79,MATCH(LARGE($KA$67:$KA$79,3),$KA$67:$KA$79,0)) | D16: =INDEX($JV$67:$JV$79,MATCH(LARGE($KA$67:$KA$79,3),$KA$67:$KA$79,0)) | E16: =INDEX($JW$67:$JW$79,MATCH(LARGE($KA$67:$KA$79,3),$KA$67:$KA$79,0)) | F16: =INDEX($JX$67:$JX$79,MATCH(LARGE($KA$67:$KA$79,3),$KA$67:$KA$79,0)) | G16: =INDEX($JY$67:$JY$79,MATCH(LARGE($KA$67:$KA$79,3),$KA$67:$KA$79,0)) | H16: =IF(G16=0,"— Sem meta",IF(C16>=G16,"✓ Meta atingida","Em andamento")) | KC16: 15 | KD16: =IF(15<=$Z$3,DATE(Configurações!$B$3,1,15),"") | KE16: =SUM($EE$67:$EE$79) | KF16: =SUM($DZ$67:$DZ$79)
A17: 4 | B17: =INDEX($A$67:$A$79,MATCH(LARGE($KA$67:$KA$79,4),$KA$67:$KA$79,0)) | C17: =INDEX($JU$67:$JU$79,MATCH(LARGE($KA$67:$KA$79,4),$KA$67:$KA$79,0)) | D17: =INDEX($JV$67:$JV$79,MATCH(LARGE($KA$67:$KA$79,4),$KA$67:$KA$79,0)) | E17: =INDEX($JW$67:$JW$79,MATCH(LARGE($KA$67:$KA$79,4),$KA$67:$KA$79,0)) | F17: =INDEX($JX$67:$JX$79,MATCH(LARGE($KA$67:$KA$79,4),$KA$67:$KA$79,0)) | G17: =INDEX($JY$67:$JY$79,MATCH(LARGE($KA$67:$KA$79,4),$KA$67:$KA$79,0)) | H17: =IF(G17=0,"— Sem meta",IF(C17>=G17,"✓ Meta atingida","Em andamento")) | KC17: 16 | KD17: =IF(16<=$Z$3,DATE(Configurações!$B$3,1,16),"") | KE17: =SUM($EN$67:$EN$79) | KF17: =SUM($EI$67:$EI$79)
A18: 5 | B18: =INDEX($A$67:$A$79,MATCH(LARGE($KA$67:$KA$79,5),$KA$67:$KA$79,0)) | C18: =INDEX($JU$67:$JU$79,MATCH(LARGE($KA$67:$KA$79,5),$KA$67:$KA$79,0)) | D18: =INDEX($JV$67:$JV$79,MATCH(LARGE($KA$67:$KA$79,5),$KA$67:$KA$79,0)) | E18: =INDEX($JW$67:$JW$79,MATCH(LARGE($KA$67:$KA$79,5),$KA$67:$KA$79,0)) | F18: =INDEX($JX$67:$JX$79,MATCH(LARGE($KA$67:$KA$79,5),$KA$67:$KA$79,0)) | G18: =INDEX($JY$67:$JY$79,MATCH(LARGE($KA$67:$KA$79,5),$KA$67:$KA$79,0)) | H18: =IF(G18=0,"— Sem meta",IF(C18>=G18,"✓ Meta atingida","Em andamento")) | KC18: 17 | KD18: =IF(17<=$Z$3,DATE(Configurações!$B$3,1,17),"") | KE18: =SUM($EW$67:$EW$79) | KF18: =SUM($ER$67:$ER$79)
A19: 6 | B19: =INDEX($A$67:$A$79,MATCH(LARGE($KA$67:$KA$79,6),$KA$67:$KA$79,0)) | C19: =INDEX($JU$67:$JU$79,MATCH(LARGE($KA$67:$KA$79,6),$KA$67:$KA$79,0)) | D19: =INDEX($JV$67:$JV$79,MATCH(LARGE($KA$67:$KA$79,6),$KA$67:$KA$79,0)) | E19: =INDEX($JW$67:$JW$79,MATCH(LARGE($KA$67:$KA$79,6),$KA$67:$KA$79,0)) | F19: =INDEX($JX$67:$JX$79,MATCH(LARGE($KA$67:$KA$79,6),$KA$67:$KA$79,0)) | G19: =INDEX($JY$67:$JY$79,MATCH(LARGE($KA$67:$KA$79,6),$KA$67:$KA$79,0)) | H19: =IF(G19=0,"— Sem meta",IF(C19>=G19,"✓ Meta atingida","Em andamento")) | KC19: 18 | KD19: =IF(18<=$Z$3,DATE(Configurações!$B$3,1,18),"") | KE19: =SUM($FF$67:$FF$79) | KF19: =SUM($FA$67:$FA$79)
A20: 7 | B20: =INDEX($A$67:$A$79,MATCH(LARGE($KA$67:$KA$79,7),$KA$67:$KA$79,0)) | C20: =INDEX($JU$67:$JU$79,MATCH(LARGE($KA$67:$KA$79,7),$KA$67:$KA$79,0)) | D20: =INDEX($JV$67:$JV$79,MATCH(LARGE($KA$67:$KA$79,7),$KA$67:$KA$79,0)) | E20: =INDEX($JW$67:$JW$79,MATCH(LARGE($KA$67:$KA$79,7),$KA$67:$KA$79,0)) | F20: =INDEX($JX$67:$JX$79,MATCH(LARGE($KA$67:$KA$79,7),$KA$67:$KA$79,0)) | G20: =INDEX($JY$67:$JY$79,MATCH(LARGE($KA$67:$KA$79,7),$KA$67:$KA$79,0)) | H20: =IF(G20=0,"— Sem meta",IF(C20>=G20,"✓ Meta atingida","Em andamento")) | KC20: 19 | KD20: =IF(19<=$Z$3,DATE(Configurações!$B$3,1,19),"") | KE20: =SUM($FO$67:$FO$79) | KF20: =SUM($FJ$67:$FJ$79)
A21: 8 | B21: =INDEX($A$67:$A$79,MATCH(LARGE($KA$67:$KA$79,8),$KA$67:$KA$79,0)) | C21: =INDEX($JU$67:$JU$79,MATCH(LARGE($KA$67:$KA$79,8),$KA$67:$KA$79,0)) | D21: =INDEX($JV$67:$JV$79,MATCH(LARGE($KA$67:$KA$79,8),$KA$67:$KA$79,0)) | E21: =INDEX($JW$67:$JW$79,MATCH(LARGE($KA$67:$KA$79,8),$KA$67:$KA$79,0)) | F21: =INDEX($JX$67:$JX$79,MATCH(LARGE($KA$67:$KA$79,8),$KA$67:$KA$79,0)) | G21: =INDEX($JY$67:$JY$79,MATCH(LARGE($KA$67:$KA$79,8),$KA$67:$KA$79,0)) | H21: =IF(G21=0,"— Sem meta",IF(C21>=G21,"✓ Meta atingida","Em andamento")) | KC21: 20 | KD21: =IF(20<=$Z$3,DATE(Configurações!$B$3,1,20),"") | KE21: =SUM($FX$67:$FX$79) | KF21: =SUM($FS$67:$FS$79)
A22: 9 | B22: =INDEX($A$67:$A$79,MATCH(LARGE($KA$67:$KA$79,9),$KA$67:$KA$79,0)) | C22: =INDEX($JU$67:$JU$79,MATCH(LARGE($KA$67:$KA$79,9),$KA$67:$KA$79,0)) | D22: =INDEX($JV$67:$JV$79,MATCH(LARGE($KA$67:$KA$79,9),$KA$67:$KA$79,0)) | E22: =INDEX($JW$67:$JW$79,MATCH(LARGE($KA$67:$KA$79,9),$KA$67:$KA$79,0)) | F22: =INDEX($JX$67:$JX$79,MATCH(LARGE($KA$67:$KA$79,9),$KA$67:$KA$79,0)) | G22: =INDEX($JY$67:$JY$79,MATCH(LARGE($KA$67:$KA$79,9),$KA$67:$KA$79,0)) | H22: =IF(G22=0,"— Sem meta",IF(C22>=G22,"✓ Meta atingida","Em andamento")) | KC22: 21 | KD22: =IF(21<=$Z$3,DATE(Configurações!$B$3,1,21),"") | KE22: =SUM($GG$67:$GG$79) | KF22: =SUM($GB$67:$GB$79)
A23: 10 | B23: =INDEX($A$67:$A$79,MATCH(LARGE($KA$67:$KA$79,10),$KA$67:$KA$79,0)) | C23: =INDEX($JU$67:$JU$79,MATCH(LARGE($KA$67:$KA$79,10),$KA$67:$KA$79,0)) | D23: =INDEX($JV$67:$JV$79,MATCH(LARGE($KA$67:$KA$79,10),$KA$67:$KA$79,0)) | E23: =INDEX($JW$67:$JW$79,MATCH(LARGE($KA$67:$KA$79,10),$KA$67:$KA$79,0)) | F23: =INDEX($JX$67:$JX$79,MATCH(LARGE($KA$67:$KA$79,10),$KA$67:$KA$79,0)) | G23: =INDEX($JY$67:$JY$79,MATCH(LARGE($KA$67:$KA$79,10),$KA$67:$KA$79,0)) | H23: =IF(G23=0,"— Sem meta",IF(C23>=G23,"✓ Meta atingida","Em andamento")) | KC23: 22 | KD23: =IF(22<=$Z$3,DATE(Configurações!$B$3,1,22),"") | KE23: =SUM($GP$67:$GP$79) | KF23: =SUM($GK$67:$GK$79)
A24: 11 | B24: =INDEX($A$67:$A$79,MATCH(LARGE($KA$67:$KA$79,11),$KA$67:$KA$79,0)) | C24: =INDEX($JU$67:$JU$79,MATCH(LARGE($KA$67:$KA$79,11),$KA$67:$KA$79,0)) | D24: =INDEX($JV$67:$JV$79,MATCH(LARGE($KA$67:$KA$79,11),$KA$67:$KA$79,0)) | E24: =INDEX($JW$67:$JW$79,MATCH(LARGE($KA$67:$KA$79,11),$KA$67:$KA$79,0)) | F24: =INDEX($JX$67:$JX$79,MATCH(LARGE($KA$67:$KA$79,11),$KA$67:$KA$79,0)) | G24: =INDEX($JY$67:$JY$79,MATCH(LARGE($KA$67:$KA$79,11),$KA$67:$KA$79,0)) | H24: =IF(G24=0,"— Sem meta",IF(C24>=G24,"✓ Meta atingida","Em andamento")) | KC24: 23 | KD24: =IF(23<=$Z$3,DATE(Configurações!$B$3,1,23),"") | KE24: =SUM($GY$67:$GY$79) | KF24: =SUM($GT$67:$GT$79)
A25: 12 | B25: =INDEX($A$67:$A$79,MATCH(LARGE($KA$67:$KA$79,12),$KA$67:$KA$79,0)) | C25: =INDEX($JU$67:$JU$79,MATCH(LARGE($KA$67:$KA$79,12),$KA$67:$KA$79,0)) | D25: =INDEX($JV$67:$JV$79,MATCH(LARGE($KA$67:$KA$79,12),$KA$67:$KA$79,0)) | E25: =INDEX($JW$67:$JW$79,MATCH(LARGE($KA$67:$KA$79,12),$KA$67:$KA$79,0)) | F25: =INDEX($JX$67:$JX$79,MATCH(LARGE($KA$67:$KA$79,12),$KA$67:$KA$79,0)) | G25: =INDEX($JY$67:$JY$79,MATCH(LARGE($KA$67:$KA$79,12),$KA$67:$KA$79,0)) | H25: =IF(G25=0,"— Sem meta",IF(C25>=G25,"✓ Meta atingida","Em andamento")) | KC25: 24 | KD25: =IF(24<=$Z$3,DATE(Configurações!$B$3,1,24),"") | KE25: =SUM($HH$67:$HH$79) | KF25: =SUM($HC$67:$HC$79)
A26: 13 | B26: =INDEX($A$67:$A$79,MATCH(LARGE($KA$67:$KA$79,13),$KA$67:$KA$79,0)) | C26: =INDEX($JU$67:$JU$79,MATCH(LARGE($KA$67:$KA$79,13),$KA$67:$KA$79,0)) | D26: =INDEX($JV$67:$JV$79,MATCH(LARGE($KA$67:$KA$79,13),$KA$67:$KA$79,0)) | E26: =INDEX($JW$67:$JW$79,MATCH(LARGE($KA$67:$KA$79,13),$KA$67:$KA$79,0)) | F26: =INDEX($JX$67:$JX$79,MATCH(LARGE($KA$67:$KA$79,13),$KA$67:$KA$79,0)) | G26: =INDEX($JY$67:$JY$79,MATCH(LARGE($KA$67:$KA$79,13),$KA$67:$KA$79,0)) | H26: =IF(G26=0,"— Sem meta",IF(C26>=G26,"✓ Meta atingida","Em andamento")) | KC26: 25 | KD26: =IF(25<=$Z$3,DATE(Configurações!$B$3,1,25),"") | KE26: =SUM($HQ$67:$HQ$79) | KF26: =SUM($HL$67:$HL$79)
KC27: 26 | KD27: =IF(26<=$Z$3,DATE(Configurações!$B$3,1,26),"") | KE27: =SUM($HZ$67:$HZ$79) | KF27: =SUM($HU$67:$HU$79)
KC28: 27 | KD28: =IF(27<=$Z$3,DATE(Configurações!$B$3,1,27),"") | KE28: =SUM($II$67:$II$79) | KF28: =SUM($ID$67:$ID$79)
KC29: 28 | KD29: =IF(28<=$Z$3,DATE(Configurações!$B$3,1,28),"") | KE29: =SUM($IR$67:$IR$79) | KF29: =SUM($IM$67:$IM$79)
KC30: 29 | KD30: =IF(29<=$Z$3,DATE(Configurações!$B$3,1,29),"") | KE30: =SUM($JA$67:$JA$79) | KF30: =SUM($IV$67:$IV$79)
KC31: 30 | KD31: =IF(30<=$Z$3,DATE(Configurações!$B$3,1,30),"") | KE31: =SUM($JJ$67:$JJ$79) | KF31: =SUM($JE$67:$JE$79)
KC32: 31 | KD32: =IF(31<=$Z$3,DATE(Configurações!$B$3,1,31),"") | KE32: =SUM($JS$67:$JS$79) | KF32: =SUM($JN$67:$JN$79)
A64: 📋 LANÇAMENTOS DIÁRIOS POR ASSESSOR (role para a direita)
A65: Assessor | B65: ="Dia 1 — "&IF(1<=$Z$3,TEXT(DATE(Configurações!$B$3,1,1),"dd/mm")&" ("&CHOOSE(WEEKDAY(DATE(Configurações!$B$3,1,1)),"Dom","Seg","Ter","Qua","Qui","Sex","Sáb")&")","—") | K65: ="Dia 2 — "&IF(2<=$Z$3,TEXT(DATE(Configurações!$B$3,1,2),"dd/mm")&" ("&CHOOSE(WEEKDAY(DATE(Configurações!$B$3,1,2)),"Dom","Seg","Ter","Qua","Qui","Sex","Sáb")&")","—") | T65: ="Dia 3 — "&IF(3<=$Z$3,TEXT(DATE(Configurações!$B$3,1,3),"dd/mm")&" ("&CHOOSE(WEEKDAY(DATE(Configurações!$B$3,1,3)),"Dom","Seg","Ter","Qua","Qui","Sex","Sáb")&")","—") | AC65: ="Dia 4 — "&IF(4<=$Z$3,TEXT(DATE(Configurações!$B$3,1,4),"dd/mm")&" ("&CHOOSE(WEEKDAY(DATE(Configurações!$B$3,1,4)),"Dom","Seg","Ter","Qua","Qui","Sex","Sáb")&")","—") | AL65: ="Dia 5 — "&IF(5<=$Z$3,TEXT(DATE(Configurações!$B$3,1,5),"dd/mm")&" ("&CHOOSE(WEEKDAY(DATE(Configurações!$B$3,1,5)),"Dom","Seg","Ter","Qua","Qui","Sex","Sáb")&")","—") | AU65: ="Dia 6 — "&IF(6<=$Z$3,TEXT(DATE(Configurações!$B$3,1,6),"dd/mm")&" ("&CHOOSE(WEEKDAY(DATE(Configurações!$B$3,1,6)),"Dom","Seg","Ter","Qua","Qui","Sex","Sáb")&")","—") | BD65: ="Dia 7 — "&IF(7<=$Z$3,TEXT(DATE(Configurações!$B$3,1,7),"dd/mm")&" ("&CHOOSE(WEEKDAY(DATE(Configurações!$B$3,1,7)),"Dom","Seg","Ter","Qua","Qui","Sex","Sáb")&")","—") | BM65: ="Dia 8 — "&IF(8<=$Z$3,TEXT(DATE(Configurações!$B$3,1,8),"dd/mm")&" ("&CHOOSE(WEEKDAY(DATE(Configurações!$B$3,1,8)),"Dom","Seg","Ter","Qua","Qui","Sex","Sáb")&")","—") | BV65: ="Dia 9 — "&IF(9<=$Z$3,TEXT(DATE(Configurações!$B$3,1,9),"dd/mm")&" ("&CHOOSE(WEEKDAY(DATE(Configurações!$B$3,1,9)),"Dom","Seg","Ter","Qua","Qui","Sex","Sáb")&")","—") | CE65: ="Dia 10 — "&IF(10<=$Z$3,TEXT(DATE(Configurações!$B$3,1,10),"dd/mm")&" ("&CHOOSE(WEEKDAY(DATE(Configurações!$B$3,1,10)),"Dom","Seg","Ter","Qua","Qui","Sex","Sáb")&")","—") | CN65: ="Dia 11 — "&IF(11<=$Z$3,TEXT(DATE(Configurações!$B$3,1,11),"dd/mm")&" ("&CHOOSE(WEEKDAY(DATE(Configurações!$B$3,1,11)),"Dom","Seg","Ter","Qua","Qui","Sex","Sáb")&")","—") | CW65: ="Dia 12 — "&IF(12<=$Z$3,TEXT(DATE(Configurações!$B$3,1,12),"dd/mm")&" ("&CHOOSE(WEEKDAY(DATE(Configurações!$B$3,1,12)),"Dom","Seg","Ter","Qua","Qui","Sex","Sáb")&")","—") | DF65: ="Dia 13 — "&IF(13<=$Z$3,TEXT(DATE(Configurações!$B$3,1,13),"dd/mm")&" ("&CHOOSE(WEEKDAY(DATE(Configurações!$B$3,1,13)),"Dom","Seg","Ter","Qua","Qui","Sex","Sáb")&")","—") | DO65: ="Dia 14 — "&IF(14<=$Z$3,TEXT(DATE(Configurações!$B$3,1,14),"dd/mm")&" ("&CHOOSE(WEEKDAY(DATE(Configurações!$B$3,1,14)),"Dom","Seg","Ter","Qua","Qui","Sex","Sáb")&")","—") | DX65: ="Dia 15 — "&IF(15<=$Z$3,TEXT(DATE(Configurações!$B$3,1,15),"dd/mm")&" ("&CHOOSE(WEEKDAY(DATE(Configurações!$B$3,1,15)),"Dom","Seg","Ter","Qua","Qui","Sex","Sáb")&")","—") | EG65: ="Dia 16 — "&IF(16<=$Z$3,TEXT(DATE(Configurações!$B$3,1,16),"dd/mm")&" ("&CHOOSE(WEEKDAY(DATE(Configurações!$B$3,1,16)),"Dom","Seg","Ter","Qua","Qui","Sex","Sáb")&")","—") | EP65: ="Dia 17 — "&IF(17<=$Z$3,TEXT(DATE(Configurações!$B$3,1,17),"dd/mm")&" ("&CHOOSE(WEEKDAY(DATE(Configurações!$B$3,1,17)),"Dom","Seg","Ter","Qua","Qui","Sex","Sáb")&")","—") | EY65: ="Dia 18 — "&IF(18<=$Z$3,TEXT(DATE(Configurações!$B$3,1,18),"dd/mm")&" ("&CHOOSE(WEEKDAY(DATE(Configurações!$B$3,1,18)),"Dom","Seg","Ter","Qua","Qui","Sex","Sáb")&")","—") | FH65: ="Dia 19 — "&IF(19<=$Z$3,TEXT(DATE(Configurações!$B$3,1,19),"dd/mm")&" ("&CHOOSE(WEEKDAY(DATE(Configurações!$B$3,1,19)),"Dom","Seg","Ter","Qua","Qui","Sex","Sáb")&")","—") | FQ65: ="Dia 20 — "&IF(20<=$Z$3,TEXT(DATE(Configurações!$B$3,1,20),"dd/mm")&" ("&CHOOSE(WEEKDAY(DATE(Configurações!$B$3,1,20)),"Dom","Seg","Ter","Qua","Qui","Sex","Sáb")&")","—") | FZ65: ="Dia 21 — "&IF(21<=$Z$3,TEXT(DATE(Configurações!$B$3,1,21),"dd/mm")&" ("&CHOOSE(WEEKDAY(DATE(Configurações!$B$3,1,21)),"Dom","Seg","Ter","Qua","Qui","Sex","Sáb")&")","—") | GI65: ="Dia 22 — "&IF(22<=$Z$3,TEXT(DATE(Configurações!$B$3,1,22),"dd/mm")&" ("&CHOOSE(WEEKDAY(DATE(Configurações!$B$3,1,22)),"Dom","Seg","Ter","Qua","Qui","Sex","Sáb")&")","—") | GR65: ="Dia 23 — "&IF(23<=$Z$3,TEXT(DATE(Configurações!$B$3,1,23),"dd/mm")&" ("&CHOOSE(WEEKDAY(DATE(Configurações!$B$3,1,23)),"Dom","Seg","Ter","Qua","Qui","Sex","Sáb")&")","—") | HA65: ="Dia 24 — "&IF(24<=$Z$3,TEXT(DATE(Configurações!$B$3,1,24),"dd/mm")&" ("&CHOOSE(WEEKDAY(DATE(Configurações!$B$3,1,24)),"Dom","Seg","Ter","Qua","Qui","Sex","Sáb")&")","—") | HJ65: ="Dia 25 — "&IF(25<=$Z$3,TEXT(DATE(Configurações!$B$3,1,25),"dd/mm")&" ("&CHOOSE(WEEKDAY(DATE(Configurações!$B$3,1,25)),"Dom","Seg","Ter","Qua","Qui","Sex","Sáb")&")","—") | HS65: ="Dia 26 — "&IF(26<=$Z$3,TEXT(DATE(Configurações!$B$3,1,26),"dd/mm")&" ("&CHOOSE(WEEKDAY(DATE(Configurações!$B$3,1,26)),"Dom","Seg","Ter","Qua","Qui","Sex","Sáb")&")","—") | IB65: ="Dia 27 — "&IF(27<=$Z$3,TEXT(DATE(Configurações!$B$3,1,27),"dd/mm")&" ("&CHOOSE(WEEKDAY(DATE(Configurações!$B$3,1,27)),"Dom","Seg","Ter","Qua","Qui","Sex","Sáb")&")","—") | IK65: ="Dia 28 — "&IF(28<=$Z$3,TEXT(DATE(Configurações!$B$3,1,28),"dd/mm")&" ("&CHOOSE(WEEKDAY(DATE(Configurações!$B$3,1,28)),"Dom","Seg","Ter","Qua","Qui","Sex","Sáb")&")","—") | IT65: ="Dia 29 — "&IF(29<=$Z$3,TEXT(DATE(Configurações!$B$3,1,29),"dd/mm")&" ("&CHOOSE(WEEKDAY(DATE(Configurações!$B$3,1,29)),"Dom","Seg","Ter","Qua","Qui","Sex","Sáb")&")","—") | JC65: ="Dia 30 — "&IF(30<=$Z$3,TEXT(DATE(Configurações!$B$3,1,30),"dd/mm")&" ("&CHOOSE(WEEKDAY(DATE(Configurações!$B$3,1,30)),"Dom","Seg","Ter","Qua","Qui","Sex","Sáb")&")","—") | JL65: ="Dia 31 — "&IF(31<=$Z$3,TEXT(DATE(Configurações!$B$3,1,31),"dd/mm")&" ("&CHOOSE(WEEKDAY(DATE(Configurações!$B$3,1,31)),"Dom","Seg","Ter","Qua","Qui","Sex","Sáb")&")","—") | JU65: Produção Total (Mês) | JV65: Captação Líquida (Mês) | JW65: Saldo Pulso Atual | JX65: Média Diária | JY65: Meta Mensal | JZ65: Status Meta
B66: Saldo Pulso | C66: Saldo Anterior | D66: Captação Líq. | E66: COE | F66: Previdência | G66: Créd. Privado | H66: Tít. Públicos | I66: Produção Tot. | J66: Obs. | K66: Saldo Pulso | L66: Saldo Anterior | M66: Captação Líq. | N66: COE | O66: Previdência | P66: Créd. Privado | Q66: Tít. Públicos | R66: Produção Tot. | S66: Obs. | T66: Saldo Pulso | U66: Saldo Anterior | V66: Captação Líq. | W66: COE | X66: Previdência | Y66: Créd. Privado | Z66: Tít. Públicos | AA66: Produção Tot. | AB66: Obs. | AC66: Saldo Pulso | AD66: Saldo Anterior | AE66: Captação Líq. | AF66: COE | AG66: Previdência | AH66: Créd. Privado | AI66: Tít. Públicos | AJ66: Produção Tot. | AK66: Obs. | AL66: Saldo Pulso | AM66: Saldo Anterior | AN66: Captação Líq. | AO66: COE | AP66: Previdência | AQ66: Créd. Privado | AR66: Tít. Públicos | AS66: Produção Tot. | AT66: Obs. | AU66: Saldo Pulso | AV66: Saldo Anterior | AW66: Captação Líq. | AX66: COE | AY66: Previdência | AZ66: Créd. Privado | BA66: Tít. Públicos | BB66: Produção Tot. | BC66: Obs. | BD66: Saldo Pulso | BE66: Saldo Anterior | BF66: Captação Líq. | BG66: COE | BH66: Previdência | BI66: Créd. Privado | BJ66: Tít. Públicos | BK66: Produção Tot. | BL66: Obs. | BM66: Saldo Pulso | BN66: Saldo Anterior | BO66: Captação Líq. | BP66: COE | BQ66: Previdência | BR66: Créd. Privado | BS66: Tít. Públicos | BT66: Produção Tot. | BU66: Obs. | BV66: Saldo Pulso | BW66: Saldo Anterior | BX66: Captação Líq. | BY66: COE | BZ66: Previdência | CA66: Créd. Privado | CB66: Tít. Públicos | CC66: Produção Tot. | CD66: Obs. | CE66: Saldo Pulso | CF66: Saldo Anterior | CG66: Captação Líq. | CH66: COE | CI66: Previdência | CJ66: Créd. Privado | CK66: Tít. Públicos | CL66: Produção Tot. | CM66: Obs. | CN66: Saldo Pulso | CO66: Saldo Anterior | CP66: Captação Líq. | CQ66: COE | CR66: Previdência | CS66: Créd. Privado | CT66: Tít. Públicos | CU66: Produção Tot. | CV66: Obs. | CW66: Saldo Pulso | CX66: Saldo Anterior | CY66: Captação Líq. | CZ66: COE | DA66: Previdência | DB66: Créd. Privado | DC66: Tít. Públicos | DD66: Produção Tot. | DE66: Obs. | DF66: Saldo Pulso | DG66: Saldo Anterior | DH66: Captação Líq. | DI66: COE | DJ66: Previdência | DK66: Créd. Privado | DL66: Tít. Públicos | DM66: Produção Tot. | DN66: Obs. | DO66: Saldo Pulso | DP66: Saldo Anterior | DQ66: Captação Líq. | DR66: COE | DS66: Previdência | DT66: Créd. Privado | DU66: Tít. Públicos | DV66: Produção Tot. | DW66: Obs. | DX66: Saldo Pulso | DY66: Saldo Anterior | DZ66: Captação Líq. | EA66: COE | EB66: Previdência | EC66: Créd. Privado | ED66: Tít. Públicos | EE66: Produção Tot. | EF66: Obs. | EG66: Saldo Pulso | EH66: Saldo Anterior | EI66: Captação Líq. | EJ66: COE | EK66: Previdência | EL66: Créd. Privado | EM66: Tít. Públicos | EN66: Produção Tot. | EO66: Obs. | EP66: Saldo Pulso | EQ66: Saldo Anterior | ER66: Captação Líq. | ES66: COE | ET66: Previdência | EU66: Créd. Privado | EV66: Tít. Públicos | EW66: Produção Tot. | EX66: Obs. | EY66: Saldo Pulso | EZ66: Saldo Anterior | FA66: Captação Líq. | FB66: COE | FC66: Previdência | FD66: Créd. Privado | FE66: Tít. Públicos | FF66: Produção Tot. | FG66: Obs. | FH66: Saldo Pulso | FI66: Saldo Anterior | FJ66: Captação Líq. | FK66: COE | FL66: Previdência | FM66: Créd. Privado | FN66: Tít. Públicos | FO66: Produção Tot. | FP66: Obs. | FQ66: Saldo Pulso | FR66: Saldo Anterior | FS66: Captação Líq. | FT66: COE | FU66: Previdência | FV66: Créd. Privado | FW66: Tít. Públicos | FX66: Produção Tot. | FY66: Obs. | FZ66: Saldo Pulso | GA66: Saldo Anterior | GB66: Captação Líq. | GC66: COE | GD66: Previdência | GE66: Créd. Privado | GF66: Tít. Públicos | GG66: Produção Tot. | GH66: Obs. | GI66: Saldo Pulso | GJ66: Saldo Anterior | GK66: Captação Líq. | GL66: COE | GM66: Previdência | GN66: Créd. Privado | GO66: Tít. Públicos | GP66: Produção Tot. | GQ66: Obs. | GR66: Saldo Pulso | GS66: Saldo Anterior | GT66: Captação Líq. | GU66: COE | GV66: Previdência | GW66: Créd. Privado | GX66: Tít. Públicos | GY66: Produção Tot. | GZ66: Obs. | HA66: Saldo Pulso | HB66: Saldo Anterior | HC66: Captação Líq. | HD66: COE | HE66: Previdência | HF66: Créd. Privado | HG66: Tít. Públicos | HH66: Produção Tot. | HI66: Obs. | HJ66: Saldo Pulso | HK66: Saldo Anterior | HL66: Captação Líq. | HM66: COE | HN66: Previdência | HO66: Créd. Privado | HP66: Tít. Públicos | HQ66: Produção Tot. | HR66: Obs. | HS66: Saldo Pulso | HT66: Saldo Anterior | HU66: Captação Líq. | HV66: COE | HW66: Previdência | HX66: Créd. Privado | HY66: Tít. Públicos | HZ66: Produção Tot. | IA66: Obs. | IB66: Saldo Pulso | IC66: Saldo Anterior | ID66: Captação Líq. | IE66: COE | IF66: Previdência | IG66: Créd. Privado | IH66: Tít. Públicos | II66: Produção Tot. | IJ66: Obs. | IK66: Saldo Pulso | IL66: Saldo Anterior | IM66: Captação Líq. | IN66: COE | IO66: Previdência | IP66: Créd. Privado | IQ66: Tít. Públicos | IR66: Produção Tot. | IS66: Obs. | IT66: Saldo Pulso | IU66: Saldo Anterior | IV66: Captação Líq. | IW66: COE | IX66: Previdência | IY66: Créd. Privado | IZ66: Tít. Públicos | JA66: Produção Tot. | JB66: Obs. | JC66: Saldo Pulso | JD66: Saldo Anterior | JE66: Captação Líq. | JF66: COE | JG66: Previdência | JH66: Créd. Privado | JI66: Tít. Públicos | JJ66: Produção Tot. | JK66: Obs. | JL66: Saldo Pulso | JM66: Saldo Anterior | JN66: Captação Líq. | JO66: COE | JP66: Previdência | JQ66: Créd. Privado | JR66: Tít. Públicos | JS66: Produção Tot. | JT66: Obs.
A67: =IF(Configurações!$B$7="","Assessor 1",Configurações!$B$7) | C67: =Configurações!$D$7 | I67: =SUM(E67:H67) | L67: =B67 | R67: =SUM(N67:Q67) | U67: =K67 | AA67: =SUM(W67:Z67) | AD67: =T67 | AJ67: =SUM(AF67:AI67) | AM67: =AC67 | AS67: =SUM(AO67:AR67) | AV67: =AL67 | BB67: =SUM(AX67:BA67) | BE67: =AU67 | BK67: =SUM(BG67:BJ67) | BN67: =BD67 | BT67: =SUM(BP67:BS67) | BW67: =BM67 | CC67: =SUM(BY67:CB67) | CF67: =BV67 | CL67: =SUM(CH67:CK67) | CO67: =CE67 | CU67: =SUM(CQ67:CT67) | CX67: =CN67 | DD67: =SUM(CZ67:DC67) | DG67: =CW67 | DM67: =SUM(DI67:DL67) | DP67: =DF67 | DV67: =SUM(DR67:DU67) | DY67: =DO67 | EE67: =SUM(EA67:ED67) | EH67: =DX67 | EN67: =SUM(EJ67:EM67) | EQ67: =EG67 | EW67: =SUM(ES67:EV67) | EZ67: =EP67 | FF67: =SUM(FB67:FE67) | FI67: =EY67 | FO67: =SUM(FK67:FN67) | FR67: =FH67 | FX67: =SUM(FT67:FW67) | GA67: =FQ67 | GG67: =SUM(GC67:GF67) | GJ67: =FZ67 | GP67: =SUM(GL67:GO67) | GS67: =GI67 | GY67: =SUM(GU67:GX67) | HB67: =GR67 | HH67: =SUM(HD67:HG67) | HK67: =HA67 | HQ67: =SUM(HM67:HP67) | HT67: =HJ67 | HZ67: =SUM(HV67:HY67) | IC67: =HS67 | II67: =SUM(IE67:IH67) | IL67: =IB67 | IR67: =SUM(IN67:IQ67) | IU67: =IK67 | JA67: =SUM(IW67:IZ67) | JD67: =IT67 | JJ67: =SUM(JF67:JI67) | JM67: =JC67 | JS67: =SUM(JO67:JR67) | JU67: =I67+R67+AA67+AJ67+AS67+BB67+BK67+BT67+CC67+CL67+CU67+DD67+DM67+DV67+EE67+EN67+EW67+FF67+FO67+FX67+GG67+GP67+GY67+HH67+HQ67+HZ67+II67+IR67+JA67+JJ67+JS67 | JV67: =D67+M67+V67+AE67+AN67+AW67+BF67+BO67+BX67+CG67+CP67+CY67+DH67+DQ67+DZ67+EI67+ER67+FA67+FJ67+FS67+GB67+GK67+GT67+HC67+HL67+HU67+ID67+IM67+IV67+JE67+JN67 | JW67: =CHOOSE($Z$3,B67, K67, T67, AC67, AL67, AU67, BD67, BM67, BV67, CE67, CN67, CW67, DF67, DO67, DX67, EG67, EP67, EY67, FH67, FQ67, FZ67, GI67, GR67, HA67, HJ67, HS67, IB67, IK67, IT67, JC67, JL67) | JX67: =IFERROR(JU67/$Z$3,0) | JY67: =Configurações!$C$7 | JZ67: =IF(JY67=0,"— Sem meta",IF(JU67>=JY67,"✓ Atingida","Em andamento")) | KA67: =JU67+(13*0.0000001)
A68: =IF(Configurações!$B$8="","Assessor 2",Configurações!$B$8) | C68: =Configurações!$D$8 | I68: =SUM(E68:H68) | L68: =B68 | R68: =SUM(N68:Q68) | U68: =K68 | AA68: =SUM(W68:Z68) | AD68: =T68 | AJ68: =SUM(AF68:AI68) | AM68: =AC68 | AS68: =SUM(AO68:AR68) | AV68: =AL68 | BB68: =SUM(AX68:BA68) | BE68: =AU68 | BK68: =SUM(BG68:BJ68) | BN68: =BD68 | BT68: =SUM(BP68:BS68) | BW68: =BM68 | CC68: =SUM(BY68:CB68) | CF68: =BV68 | CL68: =SUM(CH68:CK68) | CO68: =CE68 | CU68: =SUM(CQ68:CT68) | CX68: =CN68 | DD68: =SUM(CZ68:DC68) | DG68: =CW68 | DM68: =SUM(DI68:DL68) | DP68: =DF68 | DV68: =SUM(DR68:DU68) | DY68: =DO68 | EE68: =SUM(EA68:ED68) | EH68: =DX68 | EN68: =SUM(EJ68:EM68) | EQ68: =EG68 | EW68: =SUM(ES68:EV68) | EZ68: =EP68 | FF68: =SUM(FB68:FE68) | FI68: =EY68 | FO68: =SUM(FK68:FN68) | FR68: =FH68 | FX68: =SUM(FT68:FW68) | GA68: =FQ68 | GG68: =SUM(GC68:GF68) | GJ68: =FZ68 | GP68: =SUM(GL68:GO68) | GS68: =GI68 | GY68: =SUM(GU68:GX68) | HB68: =GR68 | HH68: =SUM(HD68:HG68) | HK68: =HA68 | HQ68: =SUM(HM68:HP68) | HT68: =HJ68 | HZ68: =SUM(HV68:HY68) | IC68: =HS68 | II68: =SUM(IE68:IH68) | IL68: =IB68 | IR68: =SUM(IN68:IQ68) | IU68: =IK68 | JA68: =SUM(IW68:IZ68) | JD68: =IT68 | JJ68: =SUM(JF68:JI68) | JM68: =JC68 | JS68: =SUM(JO68:JR68) | JU68: =I68+R68+AA68+AJ68+AS68+BB68+BK68+BT68+CC68+CL68+CU68+DD68+DM68+DV68+EE68+EN68+EW68+FF68+FO68+FX68+GG68+GP68+GY68+HH68+HQ68+HZ68+II68+IR68+JA68+JJ68+JS68 | JV68: =D68+M68+V68+AE68+AN68+AW68+BF68+BO68+BX68+CG68+CP68+CY68+DH68+DQ68+DZ68+EI68+ER68+FA68+FJ68+FS68+GB68+GK68+GT68+HC68+HL68+HU68+ID68+IM68+IV68+JE68+JN68 | JW68: =CHOOSE($Z$3,B68, K68, T68, AC68, AL68, AU68, BD68, BM68, BV68, CE68, CN68, CW68, DF68, DO68, DX68, EG68, EP68, EY68, FH68, FQ68, FZ68, GI68, GR68, HA68, HJ68, HS68, IB68, IK68, IT68, JC68, JL68) | JX68: =IFERROR(JU68/$Z$3,0) | JY68: =Configurações!$C$8 | JZ68: =IF(JY68=0,"— Sem meta",IF(JU68>=JY68,"✓ Atingida","Em andamento")) | KA68: =JU68+(12*0.0000001)
A69: =IF(Configurações!$B$9="","Assessor 3",Configurações!$B$9) | C69: =Configurações!$D$9 | I69: =SUM(E69:H69) | L69: =B69 | R69: =SUM(N69:Q69) | U69: =K69 | AA69: =SUM(W69:Z69) | AD69: =T69 | AJ69: =SUM(AF69:AI69) | AM69: =AC69 | AS69: =SUM(AO69:AR69) | AV69: =AL69 | BB69: =SUM(AX69:BA69) | BE69: =AU69 | BK69: =SUM(BG69:BJ69) | BN69: =BD69 | BT69: =SUM(BP69:BS69) | BW69: =BM69 | CC69: =SUM(BY69:CB69) | CF69: =BV69 | CL69: =SUM(CH69:CK69) | CO69: =CE69 | CU69: =SUM(CQ69:CT69) | CX69: =CN69 | DD69: =SUM(CZ69:DC69) | DG69: =CW69 | DM69: =SUM(DI69:DL69) | DP69: =DF69 | DV69: =SUM(DR69:DU69) | DY69: =DO69 | EE69: =SUM(EA69:ED69) | EH69: =DX69 | EN69: =SUM(EJ69:EM69) | EQ69: =EG69 | EW69: =SUM(ES69:EV69) | EZ69: =EP69 | FF69: =SUM(FB69:FE69) | FI69: =EY69 | FO69: =SUM(FK69:FN69) | FR69: =FH69 | FX69: =SUM(FT69:FW69) | GA69: =FQ69 | GG69: =SUM(GC69:GF69) | GJ69: =FZ69 | GP69: =SUM(GL69:GO69) | GS69: =GI69 | GY69: =SUM(GU69:GX69) | HB69: =GR69 | HH69: =SUM(HD69:HG69) | HK69: =HA69 | HQ69: =SUM(HM69:HP69) | HT69: =HJ69 | HZ69: =SUM(HV69:HY69) | IC69: =HS69 | II69: =SUM(IE69:IH69) | IL69: =IB69 | IR69: =SUM(IN69:IQ69) | IU69: =IK69 | JA69: =SUM(IW69:IZ69) | JD69: =IT69 | JJ69: =SUM(JF69:JI69) | JM69: =JC69 | JS69: =SUM(JO69:JR69) | JU69: =I69+R69+AA69+AJ69+AS69+BB69+BK69+BT69+CC69+CL69+CU69+DD69+DM69+DV69+EE69+EN69+EW69+FF69+FO69+FX69+GG69+GP69+GY69+HH69+HQ69+HZ69+II69+IR69+JA69+JJ69+JS69 | JV69: =D69+M69+V69+AE69+AN69+AW69+BF69+BO69+BX69+CG69+CP69+CY69+DH69+DQ69+DZ69+EI69+ER69+FA69+FJ69+FS69+GB69+GK69+GT69+HC69+HL69+HU69+ID69+IM69+IV69+JE69+JN69 | JW69: =CHOOSE($Z$3,B69, K69, T69, AC69, AL69, AU69, BD69, BM69, BV69, CE69, CN69, CW69, DF69, DO69, DX69, EG69, EP69, EY69, FH69, FQ69, FZ69, GI69, GR69, HA69, HJ69, HS69, IB69, IK69, IT69, JC69, JL69) | JX69: =IFERROR(JU69/$Z$3,0) | JY69: =Configurações!$C$9 | JZ69: =IF(JY69=0,"— Sem meta",IF(JU69>=JY69,"✓ Atingida","Em andamento")) | KA69: =JU69+(11*0.0000001)
A70: =IF(Configurações!$B$10="","Assessor 4",Configurações!$B$10) | C70: =Configurações!$D$10 | I70: =SUM(E70:H70) | L70: =B70 | R70: =SUM(N70:Q70) | U70: =K70 | AA70: =SUM(W70:Z70) | AD70: =T70 | AJ70: =SUM(AF70:AI70) | AM70: =AC70 | AS70: =SUM(AO70:AR70) | AV70: =AL70 | BB70: =SUM(AX70:BA70) | BE70: =AU70 | BK70: =SUM(BG70:BJ70) | BN70: =BD70 | BT70: =SUM(BP70:BS70) | BW70: =BM70 | CC70: =SUM(BY70:CB70) | CF70: =BV70 | CL70: =SUM(CH70:CK70) | CO70: =CE70 | CU70: =SUM(CQ70:CT70) | CX70: =CN70 | DD70: =SUM(CZ70:DC70) | DG70: =CW70 | DM70: =SUM(DI70:DL70) | DP70: =DF70 | DV70: =SUM(DR70:DU70) | DY70: =DO70 | EE70: =SUM(EA70:ED70) | EH70: =DX70 | EN70: =SUM(EJ70:EM70) | EQ70: =EG70 | EW70: =SUM(ES70:EV70) | EZ70: =EP70 | FF70: =SUM(FB70:FE70) | FI70: =EY70 | FO70: =SUM(FK70:FN70) | FR70: =FH70 | FX70: =SUM(FT70:FW70) | GA70: =FQ70 | GG70: =SUM(GC70:GF70) | GJ70: =FZ70 | GP70: =SUM(GL70:GO70) | GS70: =GI70 | GY70: =SUM(GU70:GX70) | HB70: =GR70 | HH70: =SUM(HD70:HG70) | HK70: =HA70 | HQ70: =SUM(HM70:HP70) | HT70: =HJ70 | HZ70: =SUM(HV70:HY70) | IC70: =HS70 | II70: =SUM(IE70:IH70) | IL70: =IB70 | IR70: =SUM(IN70:IQ70) | IU70: =IK70 | JA70: =SUM(IW70:IZ70) | JD70: =IT70 | JJ70: =SUM(JF70:JI70) | JM70: =JC70 | JS70: =SUM(JO70:JR70) | JU70: =I70+R70+AA70+AJ70+AS70+BB70+BK70+BT70+CC70+CL70+CU70+DD70+DM70+DV70+EE70+EN70+EW70+FF70+FO70+FX70+GG70+GP70+GY70+HH70+HQ70+HZ70+II70+IR70+JA70+JJ70+JS70 | JV70: =D70+M70+V70+AE70+AN70+AW70+BF70+BO70+BX70+CG70+CP70+CY70+DH70+DQ70+DZ70+EI70+ER70+FA70+FJ70+FS70+GB70+GK70+GT70+HC70+HL70+HU70+ID70+IM70+IV70+JE70+JN70 | JW70: =CHOOSE($Z$3,B70, K70, T70, AC70, AL70, AU70, BD70, BM70, BV70, CE70, CN70, CW70, DF70, DO70, DX70, EG70, EP70, EY70, FH70, FQ70, FZ70, GI70, GR70, HA70, HJ70, HS70, IB70, IK70, IT70, JC70, JL70) | JX70: =IFERROR(JU70/$Z$3,0) | JY70: =Configurações!$C$10 | JZ70: =IF(JY70=0,"— Sem meta",IF(JU70>=JY70,"✓ Atingida","Em andamento")) | KA70: =JU70+(10*0.0000001)
A71: =IF(Configurações!$B$11="","Assessor 5",Configurações!$B$11) | C71: =Configurações!$D$11 | I71: =SUM(E71:H71) | L71: =B71 | R71: =SUM(N71:Q71) | U71: =K71 | AA71: =SUM(W71:Z71) | AD71: =T71 | AJ71: =SUM(AF71:AI71) | AM71: =AC71 | AS71: =SUM(AO71:AR71) | AV71: =AL71 | BB71: =SUM(AX71:BA71) | BE71: =AU71 | BK71: =SUM(BG71:BJ71) | BN71: =BD71 | BT71: =SUM(BP71:BS71) | BW71: =BM71 | CC71: =SUM(BY71:CB71) | CF71: =BV71 | CL71: =SUM(CH71:CK71) | CO71: =CE71 | CU71: =SUM(CQ71:CT71) | CX71: =CN71 | DD71: =SUM(CZ71:DC71) | DG71: =CW71 | DM71: =SUM(DI71:DL71) | DP71: =DF71 | DV71: =SUM(DR71:DU71) | DY71: =DO71 | EE71: =SUM(EA71:ED71) | EH71: =DX71 | EN71: =SUM(EJ71:EM71) | EQ71: =EG71 | EW71: =SUM(ES71:EV71) | EZ71: =EP71 | FF71: =SUM(FB71:FE71) | FI71: =EY71 | FO71: =SUM(FK71:FN71) | FR71: =FH71 | FX71: =SUM(FT71:FW71) | GA71: =FQ71 | GG71: =SUM(GC71:GF71) | GJ71: =FZ71 | GP71: =SUM(GL71:GO71) | GS71: =GI71 | GY71: =SUM(GU71:GX71) | HB71: =GR71 | HH71: =SUM(HD71:HG71) | HK71: =HA71 | HQ71: =SUM(HM71:HP71) | HT71: =HJ71 | HZ71: =SUM(HV71:HY71) | IC71: =HS71 | II71: =SUM(IE71:IH71) | IL71: =IB71 | IR71: =SUM(IN71:IQ71) | IU71: =IK71 | JA71: =SUM(IW71:IZ71) | JD71: =IT71 | JJ71: =SUM(JF71:JI71) | JM71: =JC71 | JS71: =SUM(JO71:JR71) | JU71: =I71+R71+AA71+AJ71+AS71+BB71+BK71+BT71+CC71+CL71+CU71+DD71+DM71+DV71+EE71+EN71+EW71+FF71+FO71+FX71+GG71+GP71+GY71+HH71+HQ71+HZ71+II71+IR71+JA71+JJ71+JS71 | JV71: =D71+M71+V71+AE71+AN71+AW71+BF71+BO71+BX71+CG71+CP71+CY71+DH71+DQ71+DZ71+EI71+ER71+FA71+FJ71+FS71+GB71+GK71+GT71+HC71+HL71+HU71+ID71+IM71+IV71+JE71+JN71 | JW71: =CHOOSE($Z$3,B71, K71, T71, AC71, AL71, AU71, BD71, BM71, BV71, CE71, CN71, CW71, DF71, DO71, DX71, EG71, EP71, EY71, FH71, FQ71, FZ71, GI71, GR71, HA71, HJ71, HS71, IB71, IK71, IT71, JC71, JL71) | JX71: =IFERROR(JU71/$Z$3,0) | JY71: =Configurações!$C$11 | JZ71: =IF(JY71=0,"— Sem meta",IF(JU71>=JY71,"✓ Atingida","Em andamento")) | KA71: =JU71+(9*0.0000001)
...

Sheet Fevereiro
A1: ="ACOMPANHAMENTO DIÁRIO DE ASSESSORES — FEVEREIRO / "&Configurações!$B$3 | KC1: Dia | KD1: Data | KE1: Produção do Dia | KF1: Captação do Dia
A2: ="Dias no mês: "&$Z$3&" | Cada assessor ocupa 1 linha. Role para a direita para ver os dias. Apenas as células destacadas em amarelo são editáveis." | KC2: 1 | KD2: =IF(1<=$Z$3,DATE(Configurações!$B$3,2,1),"") | KE2: =SUM($I$67:$I$79) | KF2: =SUM($D$67:$D$79) | KH2: COE | KI2: =SUM($E$67:$E$79)+SUM($N$67:$N$79)+SUM($W$67:$W$79)+SUM($AF$67:$AF$79)+SUM($AO$67:$AO$79)+SUM($AX$67:$AX$79)+SUM($BG$67:$BG$79)+SUM($BP$67:$BP$79)+SUM($BY$67:$BY$79)+SUM($CH$67:$CH$79)+SUM($CQ$67:$CQ$79)+SUM($CZ$67:$CZ$79)+SUM($DI$67:$DI$79)+SUM($DR$67:$DR$79)+SUM($EA$67:$EA$79)+SUM($EJ$67:$EJ$79)+SUM($ES$67:$ES$79)+SUM($FB$67:$FB$79)+SUM($FK$67:$FK$79)+SUM($FT$67:$FT$79)+SUM($GC$67:$GC$79)+SUM($GL$67:$GL$79)+SUM($GU$67:$GU$79)+SUM($HD$67:$HD$79)+SUM($HM$67:$HM$79)+SUM($HV$67:$HV$79)+SUM($IE$67:$IE$79)+SUM($IN$67:$IN$79)+SUM($IW$67:$IW$79)+SUM($JF$67:$JF$79)+SUM($JO$67:$JO$79)
Y3: Dias no mês | Z3: =DAY(EOMONTH(DATE(Configurações!$B$3,2,1),0)) | KC3: 2 | KD3: =IF(2<=$Z$3,DATE(Configurações!$B$3,2,2),"") | KE3: =SUM($R$67:$R$79) | KF3: =SUM($M$67:$M$79) | KH3: PREVIDÊNCIA | KI3: =SUM($F$67:$F$79)+SUM($O$67:$O$79)+SUM($X$67:$X$79)+SUM($AG$67:$AG$79)+SUM($AP$67:$AP$79)+SUM($AY$67:$AY$79)+SUM($BH$67:$BH$79)+SUM($BQ$67:$BQ$79)+SUM($BZ$67:$BZ$79)+SUM($CI$67:$CI$79)+SUM($CR$67:$CR$79)+SUM($DA$67:$DA$79)+SUM($DJ$67:$DJ$79)+SUM($DS$67:$DS$79)+SUM($EB$67:$EB$79)+SUM($EK$67:$EK$79)+SUM($ET$67:$ET$79)+SUM($FC$67:$FC$79)+SUM($FL$67:$FL$79)+SUM($FU$67:$FU$79)+SUM($GD$67:$GD$79)+SUM($GM$67:$GM$79)+SUM($GV$67:$GV$79)+SUM($HE$67:$HE$79)+SUM($HN$67:$HN$79)+SUM($HW$67:$HW$79)+SUM($IF$67:$IF$79)+SUM($IO$67:$IO$79)+SUM($IX$67:$IX$79)+SUM($JG$67:$JG$79)+SUM($JP$67:$JP$79)
A4: 📊 INDICADORES DO MÊS | KC4: 3 | KD4: =IF(3<=$Z$3,DATE(Configurações!$B$3,2,3),"") | KE4: =SUM($AA$67:$AA$79) | KF4: =SUM($V$67:$V$79) | KH4: CRÉDITO PRIVADO | KI4: =SUM($G$67:$G$79)+SUM($P$67:$P$79)+SUM($Y$67:$Y$79)+SUM($AH$67:$AH$79)+SUM($AQ$67:$AQ$79)+SUM($AZ$67:$AZ$79)+SUM($BI$67:$BI$79)+SUM($BR$67:$BR$79)+SUM($CA$67:$CA$79)+SUM($CJ$67:$CJ$79)+SUM($CS$67:$CS$79)+SUM($DB$67:$DB$79)+SUM($DK$67:$DK$79)+SUM($DT$67:$DT$79)+SUM($EC$67:$EC$79)+SUM($EL$67:$EL$79)+SUM($EU$67:$EU$79)+SUM($FD$67:$FD$79)+SUM($FM$67:$FM$79)+SUM($FV$67:$FV$79)+SUM($GE$67:$GE$79)+SUM($GN$67:$GN$79)+SUM($GW$67:$GW$79)+SUM($HF$67:$HF$79)+SUM($HO$67:$HO$79)+SUM($HX$67:$HX$79)+SUM($IG$67:$IG$79)+SUM($IP$67:$IP$79)+SUM($IY$67:$IY$79)+SUM($JH$67:$JH$79)+SUM($JQ$67:$JQ$79)
A5: PRODUÇÃO TOTAL DO MÊS | C5: CAPTAÇÃO LÍQUIDA DO MÊS | E5: SALDO PULSO TOTAL (ATUAL) | G5: MÉDIA DIÁRIA DA EQUIPE | I5: MELHOR DIA DE PRODUÇÃO | K5: MELHOR ASSESSOR DO MÊS | KC5: 4 | KD5: =IF(4<=$Z$3,DATE(Configurações!$B$3,2,4),"") | KE5: =SUM($AJ$67:$AJ$79) | KF5: =SUM($AE$67:$AE$79) | KH5: TÍTULOS PÚBLICOS | KI5: =SUM($H$67:$H$79)+SUM($Q$67:$Q$79)+SUM($Z$67:$Z$79)+SUM($AI$67:$AI$79)+SUM($AR$67:$AR$79)+SUM($BA$67:$BA$79)+SUM($BJ$67:$BJ$79)+SUM($BS$67:$BS$79)+SUM($CB$67:$CB$79)+SUM($CK$67:$CK$79)+SUM($CT$67:$CT$79)+SUM($DC$67:$DC$79)+SUM($DL$67:$DL$79)+SUM($DU$67:$DU$79)+SUM($ED$67:$ED$79)+SUM($EM$67:$EM$79)+SUM($EV$67:$EV$79)+SUM($FE$67:$FE$79)+SUM($FN$67:$FN$79)+SUM($FW$67:$FW$79)+SUM($GF$67:$GF$79)+SUM($GO$67:$GO$79)+SUM($GX$67:$GX$79)+SUM($HG$67:$HG$79)+SUM($HP$67:$HP$79)+SUM($HY$67:$HY$79)+SUM($IH$67:$IH$79)+SUM($IQ$67:$IQ$79)+SUM($IZ$67:$IZ$79)+SUM($JI$67:$JI$79)+SUM($JR$67:$JR$79)
A6: =SUM($JU$67:$JU$79) | C6: =SUM($JV$67:$JV$79) | E6: =SUM($JW$67:$JW$79) | G6: =IFERROR(SUM($JU$67:$JU$79)/$Z$3,0) | I6: =IFERROR("Dia "&TEXT(INDEX($KD$2:$KD$32,MATCH(MAX($KE$2:$KE$32),$KE$2:$KE$32,0)),"dd/mm")&" - "&TEXT(MAX($KE$2:$KE$32),"R$ #,##0"),"—") | K6: =IFERROR($B$14&" - "&TEXT($C$14,"R$ #,##0"),"—") | KC6: 5 | KD6: =IF(5<=$Z$3,DATE(Configurações!$B$3,2,5),"") | KE6: =SUM($AS$67:$AS$79) | KF6: =SUM($AN$67:$AN$79)
KC7: 6 | KD7: =IF(6<=$Z$3,DATE(Configurações!$B$3,2,6),"") | KE7: =SUM($BB$67:$BB$79) | KF7: =SUM($AW$67:$AW$79)
A8: 💰 TOTAIS POR PRODUTO | KC8: 7 | KD8: =IF(7<=$Z$3,DATE(Configurações!$B$3,2,7),"") | KE8: =SUM($BK$67:$BK$79) | KF8: =SUM($BF$67:$BF$79)
A9: COE | D9: PREVIDÊNCIA | G9: CRÉDITO PRIVADO | J9: TÍTULOS PÚBLICOS | KC9: 8 | KD9: =IF(8<=$Z$3,DATE(Configurações!$B$3,2,8),"") | KE9: =SUM($BT$67:$BT$79) | KF9: =SUM($BO$67:$BO$79)
A10: =SUM($E$67:$E$79)+SUM($N$67:$N$79)+SUM($W$67:$W$79)+SUM($AF$67:$AF$79)+SUM($AO$67:$AO$79)+SUM($AX$67:$AX$79)+SUM($BG$67:$BG$79)+SUM($BP$67:$BP$79)+SUM($BY$67:$BY$79)+SUM($CH$67:$CH$79)+SUM($CQ$67:$CQ$79)+SUM($CZ$67:$CZ$79)+SUM($DI$67:$DI$79)+SUM($DR$67:$DR$79)+SUM($EA$67:$EA$79)+SUM($EJ$67:$EJ$79)+SUM($ES$67:$ES$79)+SUM($FB$67:$FB$79)+SUM($FK$67:$FK$79)+SUM($FT$67:$FT$79)+SUM($GC$67:$GC$79)+SUM($GL$67:$GL$79)+SUM($GU$67:$GU$79)+SUM($HD$67:$HD$79)+SUM($HM$67:$HM$79)+SUM($HV$67:$HV$79)+SUM($IE$67:$IE$79)+SUM($IN$67:$IN$79)+SUM($IW$67:$IW$79)+SUM($JF$67:$JF$79)+SUM($JO$67:$JO$79) | D10: =SUM($F$67:$F$79)+SUM($O$67:$O$79)+SUM($X$67:$X$79)+SUM($AG$67:$AG$79)+SUM($AP$67:$AP$79)+SUM($AY$67:$AY$79)+SUM($BH$67:$BH$79)+SUM($BQ$67:$BQ$79)+SUM($BZ$67:$BZ$79)+SUM($CI$67:$CI$79)+SUM($CR$67:$CR$79)+SUM($DA$67:$DA$79)+SUM($DJ$67:$DJ$79)+SUM($DS$67:$DS$79)+SUM($EB$67:$EB$79)+SUM($EK$67:$EK$79)+SUM($ET$67:$ET$79)+SUM($FC$67:$FC$79)+SUM($FL$67:$FL$79)+SUM($FU$67:$FU$79)+SUM($GD$67:$GD$79)+SUM($GM$67:$GM$79)+SUM($GV$67:$GV$79)+SUM($HE$67:$HE$79)+SUM($HN$67:$HN$79)+SUM($HW$67:$HW$79)+SUM($IF$67:$IF$79)+SUM($IO$67:$IO$79)+SUM($IX$67:$IX$79)+SUM($JG$67:$JG$79)+SUM($JP$67:$JP$79) | G10: =SUM($G$67:$G$79)+SUM($P$67:$P$79)+SUM($Y$67:$Y$79)+SUM($AH$67:$AH$79)+SUM($AQ$67:$AQ$79)+SUM($AZ$67:$AZ$79)+SUM($BI$67:$BI$79)+SUM($BR$67:$BR$79)+SUM($CA$67:$CA$79)+SUM($CJ$67:$CJ$79)+SUM($CS$67:$CS$79)+SUM($DB$67:$DB$79)+SUM($DK$67:$DK$79)+SUM($DT$67:$DT$79)+SUM($EC$67:$EC$79)+SUM($EL$67:$EL$79)+SUM($EU$67:$EU$79)+SUM($FD$67:$FD$79)+SUM($FM$67:$FM$79)+SUM($FV$67:$FV$79)+SUM($GE$67:$GE$79)+SUM($GN$67:$GN$79)+SUM($GW$67:$GW$79)+SUM($HF$67:$HF$79)+SUM($HO$67:$HO$79)+SUM($HX$67:$HX$79)+SUM($IG$67:$IG$79)+SUM($IP$67:$IP$79)+SUM($IY$67:$IY$79)+SUM($JH$67:$JH$79)+SUM($JQ$67:$JQ$79) | J10: =SUM($H$67:$H$79)+SUM($Q$67:$Q$79)+SUM($Z$67:$Z$79)+SUM($AI$67:$AI$79)+SUM($AR$67:$AR$79)+SUM($BA$67:$BA$79)+SUM($BJ$67:$BJ$79)+SUM($BS$67:$BS$79)+SUM($CB$67:$CB$79)+SUM($CK$67:$CK$79)+SUM($CT$67:$CT$79)+SUM($DC$67:$DC$79)+SUM($DL$67:$DL$79)+SUM($DU$67:$DU$79)+SUM($ED$67:$ED$79)+SUM($EM$67:$EM$79)+SUM($EV$67:$EV$79)+SUM($FE$67:$FE$79)+SUM($FN$67:$FN$79)+SUM($FW$67:$FW$79)+SUM($GF$67:$GF$79)+SUM($GO$67:$GO$79)+SUM($GX$67:$GX$79)+SUM($HG$67:$HG$79)+SUM($HP$67:$HP$79)+SUM($HY$67:$HY$79)+SUM($IH$67:$IH$79)+SUM($IQ$67:$IQ$79)+SUM($IZ$67:$IZ$79)+SUM($JI$67:$JI$79)+SUM($JR$67:$JR$79) | KC10: 9 | KD10: =IF(9<=$Z$3,DATE(Configurações!$B$3,2,9),"") | KE10: =SUM($CC$67:$CC$79) | KF10: =SUM($BX$67:$BX$79)
KC11: 10 | KD11: =IF(10<=$Z$3,DATE(Configurações!$B$3,2,10),"") | KE11: =SUM($CL$67:$CL$79) | KF11: =SUM($CG$67:$CG$79)
A12: 🏆 RANKING DE ASSESSORES (TOP 5 EM DESTAQUE) | KC12: 11 | KD12: =IF(11<=$Z$3,DATE(Configurações!$B$3,2,11),"") | KE12: =SUM($CU$67:$CU$79) | KF12: =SUM($CP$67:$CP$79)
A13: Pos. | B13: Assessor | C13: Produção Total | D13: Captação Líquida | E13: Saldo Pulso Atual | F13: Média Diária | G13: Meta Mensal | H13: Status | KC13: 12 | KD13: =IF(12<=$Z$3,DATE(Configurações!$B$3,2,12),"") | KE13: =SUM($DD$67:$DD$79) | KF13: =SUM($CY$67:$CY$79)
A14: 1 | B14: =INDEX($A$67:$A$79,MATCH(LARGE($KA$67:$KA$79,1),$KA$67:$KA$79,0)) | C14: =INDEX($JU$67:$JU$79,MATCH(LARGE($KA$67:$KA$79,1),$KA$67:$KA$79,0)) | D14: =INDEX($JV$67:$JV$79,MATCH(LARGE($KA$67:$KA$79,1),$KA$67:$KA$79,0)) | E14: =INDEX($JW$67:$JW$79,MATCH(LARGE($KA$67:$KA$79,1),$KA$67:$KA$79,0)) | F14: =INDEX($JX$67:$JX$79,MATCH(LARGE($KA$67:$KA$79,1),$KA$67:$KA$79,0)) | G14: =INDEX($JY$67:$JY$79,MATCH(LARGE($KA$67:$KA$79,1),$KA$67:$KA$79,0)) | H14: =IF(G14=0,"— Sem meta",IF(C14>=G14,"✓ Meta atingida","Em andamento")) | KC14: 13 | KD14: =IF(13<=$Z$3,DATE(Configurações!$B$3,2,13),"") | KE14: =SUM($DM$67:$DM$79) | KF14: =SUM($DH$67:$DH$79)
A15: 2 | B15: =INDEX($A$67:$A$79,MATCH(LARGE($KA$67:$KA$79,2),$KA$67:$KA$79,0)) | C15: =INDEX($JU$67:$JU$79,MATCH(LARGE($KA$67:$KA$79,2),$KA$67:$KA$79,0)) | D15: =INDEX($JV$67:$JV$79,MATCH(LARGE($KA$67:$KA$79,2),$KA$67:$KA$79,0)) | E15: =INDEX($JW$67:$JW$79,MATCH(LARGE($KA$67:$KA$79,2),$KA$67:$KA$79,0)) | F15: =INDEX($JX$67:$JX$79,MATCH(LARGE($KA$67:$KA$79,2),$KA$67:$KA$79,0)) | G15: =INDEX($JY$67:$JY$79,MATCH(LARGE($KA$67:$KA$79,2),$KA$67:$KA$79,0)) | H15: =IF(G15=0,"— Sem meta",IF(C15>=G15,"✓ Meta atingida","Em andamento")) | KC15: 14 | KD15: =IF(14<=$Z$3,DATE(Configurações!$B$3,2,14),"") | KE15: =SUM($DV$67:$DV$79) | KF15: =SUM($DQ$67:$DQ$79)
A16: 3 | B16: =INDEX($A$67:$A$79,MATCH(LARGE($KA$67:$KA$79,3),$KA$67:$KA$79,0)) | C16: =INDEX($JU$67:$JU$79,MATCH(LARGE($KA$67:$KA$79,3),$KA$67:$KA$79,0)) | D16: =INDEX($JV$67:$JV$79,MATCH(LARGE($KA$67:$KA$79,3),$KA$67:$KA$79,0)) | E16: =INDEX($JW$67:$JW$79,MATCH(LARGE($KA$67:$KA$79,3),$KA$67:$KA$79,0)) | F16: =INDEX($JX$67:$JX$79,MATCH(LARGE($KA$67:$KA$79,3),$KA$67:$KA$79,0)) | G16: =INDEX($JY$67:$JY$79,MATCH(LARGE($KA$67:$KA$79,3),$KA$67:$KA$79,0)) | H16: =IF(G16=0,"— Sem meta",IF(C16>=G16,"✓ Meta atingida","Em andamento")) | KC16: 15 | KD16: =IF(15<=$Z$3,DATE(Configurações!$B$3,2,15),"") | KE16: =SUM($EE$67:$EE$79) | KF16: =SUM($DZ$67:$DZ$79)
A17: 4 | B17: =INDEX($A$67:$A$79,MATCH(LARGE($KA$67:$KA$79,4),$KA$67:$KA$79,0)) | C17: =INDEX($JU$67:$JU$79,MATCH(LARGE($KA$67:$KA$79,4),$KA$67:$KA$79,0)) | D17: =INDEX($JV$67:$JV$79,MATCH(LARGE($KA$67:$KA$79,4),$KA$67:$KA$79,0)) | E17: =INDEX($JW$67:$JW$79,MATCH(LARGE($KA$67:$KA$79,4),$KA$67:$KA$79,0)) | F17: =INDEX($JX$67:$JX$79,MATCH(LARGE($KA$67:$KA$79,4),$KA$67:$KA$79,0)) | G17: =INDEX($JY$67:$JY$79,MATCH(LARGE($KA$67:$KA$79,4),$KA$67:$KA$79,0)) | H17: =IF(G17=0,"— Sem meta",IF(C17>=G17,"✓ Meta atingida","Em andamento")) | KC17: 16 | KD17: =IF(16<=$Z$3,DATE(Configurações!$B$3,2,16),"") | KE17: =SUM($EN$67:$EN$79) | KF17: =SUM($EI$67:$EI$79)
A18: 5 | B18: =INDEX($A$67:$A$79,MATCH(LARGE($KA$67:$KA$79,5),$KA$67:$KA$79,0)) | C18: =INDEX($JU$67:$JU$79,MATCH(LARGE($KA$67:$KA$79,5),$KA$67:$KA$79,0)) | D18: =INDEX($JV$67:$JV$79,MATCH(LARGE($KA$67:$KA$79,5),$KA$67:$KA$79,0)) | E18: =INDEX($JW$67:$JW$79,MATCH(LARGE($KA$67:$KA$79,5),$KA$67:$KA$79,0)) | F18: =INDEX($JX$67:$JX$79,MATCH(LARGE($KA$67:$KA$79,5),$KA$67:$KA$79,0)) | G18: =INDEX($JY$67:$JY$79,MATCH(LARGE($KA$67:$KA$79,5),$KA$67:$KA$79,0)) | H18: =IF(G18=0,"— Sem meta",IF(C18>=G18,"✓ Meta atingida","Em andamento")) | KC18: 17 | KD18: =IF(17<=$Z$3,DATE(Configurações!$B$3,2,17),"") | KE18: =SUM($EW$67:$EW$79) | KF18: =SUM($ER$67:$ER$79)
A19: 6 | B19: =INDEX($A$67:$A$79,MATCH(LARGE($KA$67:$KA$79,6),$KA$67:$KA$79,0)) | C19: =INDEX($JU$67:$JU$79,MATCH(LARGE($KA$67:$KA$79,6),$KA$67:$KA$79,0)) | D19: =INDEX($JV$67:$JV$79,MATCH(LARGE($KA$67:$KA$79,6),$KA$67:$KA$79,0)) | E19: =INDEX($JW$67:$JW$79,MATCH(LARGE($KA$67:$KA$79,6),$KA$67:$KA$79,0)) | F19: =INDEX($JX$67:$JX$79,MATCH(LARGE($KA$67:$KA$79,6),$KA$67:$KA$79,0)) | G19: =INDEX($JY$67:$JY$79,MATCH(LARGE($KA$67:$KA$79,6),$KA$67:$KA$79,0)) | H19: =IF(G19=0,"— Sem meta",IF(C19>=G19,"✓ Meta atingida","Em andamento")) | KC19: 18 | KD19: =IF(18<=$Z$3,DATE(Configurações!$B$3,2,18),"") | KE19: =SUM($FF$67:$FF$79) | KF19: =SUM($FA$67:$FA$79)
A20: 7 | B20: =INDEX($A$67:$A$79,MATCH(LARGE($KA$67:$KA$79,7),$KA$67:$KA$79,0)) | C20: =INDEX($JU$67:$JU$79,MATCH(LARGE($KA$67:$KA$79,7),$KA$67:$KA$79,0)) | D20: =INDEX($JV$67:$JV$79,MATCH(LARGE($KA$67:$KA$79,7),$KA$67:$KA$79,0)) | E20: =INDEX($JW$67:$JW$79,MATCH(LARGE($KA$67:$KA$79,7),$KA$67:$KA$79,0)) | F20: =INDEX($JX$67:$JX$79,MATCH(LARGE($KA$67:$KA$79,7),$KA$67:$KA$79,0)) | G20: =INDEX($JY$67:$JY$79,MATCH(LARGE($KA$67:$KA$79,7),$KA$67:$KA$79,0)) | H20: =IF(G20=0,"— Sem meta",IF(C20>=G20,"✓ Meta atingida","Em andamento")) | KC20: 19 | KD20: =IF(19<=$Z$3,DATE(Configurações!$B$3,2,19),"") | KE20: =SUM($FO$67:$FO$79) | KF20: =SUM($FJ$67:$FJ$79)
A21: 8 | B21: =INDEX($A$67:$A$79,MATCH(LARGE($KA$67:$KA$79,8),$KA$67:$KA$79,0)) | C21: =INDEX($JU$67:$JU$79,MATCH(LARGE($KA$67:$KA$79,8),$KA$67:$KA$79,0)) | D21: =INDEX($JV$67:$JV$79,MATCH(LARGE($KA$67:$KA$79,8),$KA$67:$KA$79,0)) | E21: =INDEX($JW$67:$JW$79,MATCH(LARGE($KA$67:$KA$79,8),$KA$67:$KA$79,0)) | F21: =INDEX($JX$67:$JX$79,MATCH(LARGE($KA$67:$KA$79,8),$KA$67:$KA$79,0)) | G21: =INDEX($JY$67:$JY$79,MATCH(LARGE($KA$67:$KA$79,8),$KA$67:$KA$79,0)) | H21: =IF(G21=0,"— Sem meta",IF(C21>=G21,"✓ Meta atingida","Em andamento")) | KC21: 20 | KD21: =IF(20<=$Z$3,DATE(Configurações!$B$3,2,20),"") | KE21: =SUM($FX$67:$FX$79) | KF21: =SUM($FS$67:$FS$79)
A22: 9 | B22: =INDEX($A$67:$A$79,MATCH(LARGE($KA$67:$KA$79,9),$KA$67:$KA$79,0)) | C22: =INDEX($JU$67:$JU$79,MATCH(LARGE($KA$67:$KA$79,9),$KA$67:$KA$79,0)) | D22: =INDEX($JV$67:$JV$79,MATCH(LARGE($KA$67:$KA$79,9),$KA$67:$KA$79,0)) | E22: =INDEX($JW$67:$JW$79,MATCH(LARGE($KA$67:$KA$79,9),$KA$67:$KA$79,0)) | F22: =INDEX($JX$67:$JX$79,MATCH(LARGE($KA$67:$KA$79,9),$KA$67:$KA$79,0)) | G22: =INDEX($JY$67:$JY$79,MATCH(LARGE($KA$67:$KA$79,9),$KA$67:$KA$79,0)) | H22: =IF(G22=0,"— Sem meta",IF(C22>=G22,"✓ Meta atingida","Em andamento")) | KC22: 21 | KD22: =IF(21<=$Z$3,DATE(Configurações!$B$3,2,21),"") | KE22: =SUM($GG$67:$GG$79) | KF22: =SUM($GB$67:$GB$79)
A23: 10 | B23: =INDEX($A$67:$A$79,MATCH(LARGE($KA$67:$KA$79,10),$KA$67:$KA$79,0)) | C23: =INDEX($JU$67:$JU$79,MATCH(LARGE($KA$67:$KA$79,10),$KA$67:$KA$79,0)) | D23: =INDEX($JV$67:$JV$79,MATCH(LARGE($KA$67:$KA$79,10),$KA$67:$KA$79,0)) | E23: =INDEX($JW$67:$JW$79,MATCH(LARGE($KA$67:$KA$79,10),$KA$67:$KA$79,0)) | F23: =INDEX($JX$67:$JX$79,MATCH(LARGE($KA$67:$KA$79,10),$KA$67:$KA$79,0)) | G23: =INDEX($JY$67:$JY$79,MATCH(LARGE($KA$67:$KA$79,10),$KA$67:$KA$79,0)) | H23: =IF(G23=0,"— Sem meta",IF(C23>=G23,"✓ Meta atingida","Em andamento")) | KC23: 22 | KD23: =IF(22<=$Z$3,DATE(Configurações!$B$3,2,22),"") | KE23: =SUM($GP$67:$GP$79) | KF23: =SUM($GK$67:$GK$79)
A24: 11 | B24: =INDEX($A$67:$A$79,MATCH(LARGE($KA$67:$KA$79,11),$KA$67:$KA$79,0)) | C24: =INDEX($JU$67:$JU$79,MATCH(LARGE($KA$67:$KA$79,11),$KA$67:$KA$79,0)) | D24: =INDEX($JV$67:$JV$79,MATCH(LARGE($KA$67:$KA$79,11),$KA$67:$KA$79,0)) | E24: =INDEX($JW$67:$JW$79,MATCH(LARGE($KA$67:$KA$79,11),$KA$67:$KA$79,0)) | F24: =INDEX($JX$67:$JX$79,MATCH(LARGE($KA$67:$KA$79,11),$KA$67:$KA$79,0)) | G24: =INDEX($JY$67:$JY$79,MATCH(LARGE($KA$67:$KA$79,11),$KA$67:$KA$79,0)) | H24: =IF(G24=0,"— Sem meta",IF(C24>=G24,"✓ Meta atingida","Em andamento")) | KC24: 23 | KD24: =IF(23<=$Z$3,DATE(Configurações!$B$3,2,23),"") | KE24: =SUM($GY$67:$GY$79) | KF24: =SUM($GT$67:$GT$79)
A25: 12 | B25: =INDEX($A$67:$A$79,MATCH(LARGE($KA$67:$KA$79,12),$KA$67:$KA$79,0)) | C25: =INDEX($JU$67:$JU$79,MATCH(LARGE($KA$67:$KA$79,12),$KA$67:$KA$79,0)) | D25: =INDEX($JV$67:$JV$79,MATCH(LARGE($KA$67:$KA$79,12),$KA$67:$KA$79,0)) | E25: =INDEX($JW$67:$JW$79,MATCH(LARGE($KA$67:$KA$79,12),$KA$67:$KA$79,0)) | F25: =INDEX($JX$67:$JX$79,MATCH(LARGE($KA$67:$KA$79,12),$KA$67:$KA$79,0)) | G25: =INDEX($JY$67:$JY$79,MATCH(LARGE($KA$67:$KA$79,12),$KA$67:$KA$79,0)) | H25: =IF(G25=0,"— Sem meta",IF(C25>=G25,"✓ Meta atingida","Em andamento")) | KC25: 24 | KD25: =IF(24<=$Z$3,DATE(Configurações!$B$3,2,24),"") | KE25: =SUM($HH$67:$HH$79) | KF25: =SUM($HC$67:$HC$79)
A26: 13 | B26: =INDEX($A$67:$A$79,MATCH(LARGE($KA$67:$KA$79,13),$KA$67:$KA$79,0)) | C26: =INDEX($JU$67:$JU$79,MATCH(LARGE($KA$67:$KA$79,13),$KA$67:$KA$79,0)) | D26: =INDEX($JV$67:$JV$79,MATCH(LARGE($KA$67:$KA$79,13),$KA$67:$KA$79,0)) | E26: =INDEX($JW$67:$JW$79,MATCH(LARGE($KA$67:$KA$79,13),$KA$67:$KA$79,0)) | F26: =INDEX($JX$67:$JX$79,MATCH(LARGE($KA$67:$KA$79,13),$KA$67:$KA$79,0)) | G26: =INDEX($JY$67:$JY$79,MATCH(LARGE($KA$67:$KA$79,13),$KA$67:$KA$79,0)) | H26: =IF(G26=0,"— Sem meta",IF(C26>=G26,"✓ Meta atingida","Em andamento")) | KC26: 25 | KD26: =IF(25<=$Z$3,DATE(Configurações!$B$3,2,25),"") | KE26: =SUM($HQ$67:$HQ$79) | KF26: =SUM($HL$67:$HL$79)
KC27: 26 | KD27: =IF(26<=$Z$3,DATE(Configurações!$B$3,2,26),"") | KE27: =SUM($HZ$67:$HZ$79) | KF27: =SUM($HU$67:$HU$79)
KC28: 27 | KD28: =IF(27<=$Z$3,DATE(Configurações!$B$3,2,27),"") | KE28: =SUM($II$67:$II$79) | KF28: =SUM($ID$67:$ID$79)
KC29: 28 | KD29: =IF(28<=$Z$3,DATE(Configurações!$B$3,2,28),"") | KE29: =SUM($IR$67:$IR$79) | KF29: =SUM($IM$67:$IM$79)
KC30: 29 | KD30: =IF(29<=$Z$3,DATE(Configurações!$B$3,2,29),"") | KE30: =SUM($JA$67:$JA$79) | KF30: =SUM($IV$67:$IV$79)
KC31: 30 | KD31: =IF(30<=$Z$3,DATE(Configurações!$B$3,2,30),"") | KE31: =SUM($JJ$67:$JJ$79) | KF31: =SUM($JE$67:$JE$79)
KC32: 31 | KD32: =IF(31<=$Z$3,DATE(Configurações!$B$3,2,31),"") | KE32: =SUM($JS$67:$JS$79) | KF32: =SUM($JN$67:$JN$79)
A64: 📋 LANÇAMENTOS DIÁRIOS POR ASSESSOR (role para a direita)
