Workbook

Sheet Clientes
A1: CADASTRO DE CLIENTES
A2: Penumper | B2: Nome | C2: CPF

Sheet Aplicacoes
A1: BASE DE APLICAÇÕES — POSIÇÃO ATUAL
A2: Penumper | B2: Mês (AAAAMM) | C2: Produto | D2: Subproduto | E2: Vencimento | F2: Saldo Ponta | G2: Idade | H2: Nome (automático) | I2: CPF (automático) | J2: rk
H3: =IF($A3="","",IFERROR(VLOOKUP($A3,Clientes!$A$3:$C$1002,2,0),"NÃO CADASTRADO")) | I3: =IF($A3="","",IFERROR(VLOOKUP($A3,Clientes!$A$3:$C$1002,3,0),"NÃO CADASTRADO")) | J3: =IF($A3="","",IF($A3='Carteira do Cliente'!$B$4,COUNTIF($A$3:$A3,'Carteira do Cliente'!$B$4),""))
H4: =IF($A4="","",IFERROR(VLOOKUP($A4,Clientes!$A$3:$C$1002,2,0),"NÃO CADASTRADO")) | I4: =IF($A4="","",IFERROR(VLOOKUP($A4,Clientes!$A$3:$C$1002,3,0),"NÃO CADASTRADO")) | J4: =IF($A4="","",IF($A4='Carteira do Cliente'!$B$4,COUNTIF($A$3:$A4,'Carteira do Cliente'!$B$4),""))
H5: =IF($A5="","",IFERROR(VLOOKUP($A5,Clientes!$A$3:$C$1002,2,0),"NÃO CADASTRADO")) | I5: =IF($A5="","",IFERROR(VLOOKUP($A5,Clientes!$A$3:$C$1002,3,0),"NÃO CADASTRADO")) | J5: =IF($A5="","",IF($A5='Carteira do Cliente'!$B$4,COUNTIF($A$3:$A5,'Carteira do Cliente'!$B$4),""))
H6: =IF($A6="","",IFERROR(VLOOKUP($A6,Clientes!$A$3:$C$1002,2,0),"NÃO CADASTRADO")) | I6: =IF($A6="","",IFERROR(VLOOKUP($A6,Clientes!$A$3:$C$1002,3,0),"NÃO CADASTRADO")) | J6: =IF($A6="","",IF($A6='Carteira do Cliente'!$B$4,COUNTIF($A$3:$A6,'Carteira do Cliente'!$B$4),""))
H7: =IF($A7="","",IFERROR(VLOOKUP($A7,Clientes!$A$3:$C$1002,2,0),"NÃO CADASTRADO")) | I7: =IF($A7="","",IFERROR(VLOOKUP($A7,Clientes!$A$3:$C$1002,3,0),"NÃO CADASTRADO")) | J7: =IF($A7="","",IF($A7='Carteira do Cliente'!$B$4,COUNTIF($A$3:$A7,'Carteira do Cliente'!$B$4),""))
H8: =IF($A8="","",IFERROR(VLOOKUP($A8,Clientes!$A$3:$C$1002,2,0),"NÃO CADASTRADO")) | I8: =IF($A8="","",IFERROR(VLOOKUP($A8,Clientes!$A$3:$C$1002,3,0),"NÃO CADASTRADO")) | J8: =IF($A8="","",IF($A8='Carteira do Cliente'!$B$4,COUNTIF($A$3:$A8,'Carteira do Cliente'!$B$4),""))
H9: =IF($A9="","",IFERROR(VLOOKUP($A9,Clientes!$A$3:$C$1002,2,0),"NÃO CADASTRADO")) | I9: =IF($A9="","",IFERROR(VLOOKUP($A9,Clientes!$A$3:$C$1002,3,0),"NÃO CADASTRADO")) | J9: =IF($A9="","",IF($A9='Carteira do Cliente'!$B$4,COUNTIF($A$3:$A9,'Carteira do Cliente'!$B$4),""))
H10: =IF($A10="","",IFERROR(VLOOKUP($A10,Clientes!$A$3:$C$1002,2,0),"NÃO CADASTRADO")) | I10: =IF($A10="","",IFERROR(VLOOKUP($A10,Clientes!$A$3:$C$1002,3,0),"NÃO CADASTRADO")) | J10: =IF($A10="","",IF($A10='Carteira do Cliente'!$B$4,COUNTIF($A$3:$A10,'Carteira do Cliente'!$B$4),""))
H11: =IF($A11="","",IFERROR(VLOOKUP($A11,Clientes!$A$3:$C$1002,2,0),"NÃO CADASTRADO")) | I11: =IF($A11="","",IFERROR(VLOOKUP($A11,Clientes!$A$3:$C$1002,3,0),"NÃO CADASTRADO")) | J11: =IF($A11="","",IF($A11='Carteira do Cliente'!$B$4,COUNTIF($A$3:$A11,'Carteira do Cliente'!$B$4),""))
H12: =IF($A12="","",IFERROR(VLOOKUP($A12,Clientes!$A$3:$C$1002,2,0),"NÃO CADASTRADO")) | I12: =IF($A12="","",IFERROR(VLOOKUP($A12,Clientes!$A$3:$C$1002,3,0),"NÃO CADASTRADO")) | J12: =IF($A12="","",IF($A12='Carteira do Cliente'!$B$4,COUNTIF($A$3:$A12,'Carteira do Cliente'!$B$4),""))
H13: =IF($A13="","",IFERROR(VLOOKUP($A13,Clientes!$A$3:$C$1002,2,0),"NÃO CADASTRADO")) | I13: =IF($A13="","",IFERROR(VLOOKUP($A13,Clientes!$A$3:$C$1002,3,0),"NÃO CADASTRADO")) | J13: =IF($A13="","",IF($A13='Carteira do Cliente'!$B$4,COUNTIF($A$3:$A13,'Carteira do Cliente'!$B$4),""))
H14: =IF($A14="","",IFERROR(VLOOKUP($A14,Clientes!$A$3:$C$1002,2,0),"NÃO CADASTRADO")) | I14: =IF($A14="","",IFERROR(VLOOKUP($A14,Clientes!$A$3:$C$1002,3,0),"NÃO CADASTRADO")) | J14: =IF($A14="","",IF($A14='Carteira do Cliente'!$B$4,COUNTIF($A$3:$A14,'Carteira do Cliente'!$B$4),""))
... H1002: =IF($A1002="","",IFERROR(VLOOKUP($A1002,Clientes!$A$3:$C$1002,2,0),"NÃO CADASTRADO")) | I1002: =IF($A1002="","",IFERROR(VLOOKUP($A1002,Clientes!$A$3:$C$1002,3,0),"NÃO CADASTRADO")) | J1002: =IF($A1002="","",IF($A1002='Carteira do Cliente'!$B$4,COUNTIF($A$3:$A1002,'Carteira do Cliente'!$B$4),""))

Sheet Carteira do Cliente
A1: CARTEIRA DO CLIENTE — POSIÇÃO ATUAL
A3: Cliente:
A4: Penumper: | B4: =IFERROR(INDEX(Clientes!$A$3:$A$1002,MATCH($B$3,Clientes!$B$3:$B$1002,0)),"")
A5: CPF: | B5: =IFERROR(INDEX(Clientes!$C$3:$C$1002,MATCH($B$3,Clientes!$B$3:$B$1002,0)),"")
A6: Patrimônio total: | B6: =SUMIFS(Aplicacoes!$F$3:$F$1002,Aplicacoes!$A$3:$A$1002,$B$4)
A7: Nº de aplicações: | B7: =COUNTIF(Aplicacoes!$A$3:$A$1002,$B$4)
A9: ALOCAÇÃO POR PRODUTO / CLASSE
A10: Classe | B10: Filtro (contém) | C10: Saldo (R$) | D10: % da carteira
A11: Fundos | B11: FUNDOS | C11: =IF($B11="",0,SUMIFS(Aplicacoes!$F$3:$F$1002,Aplicacoes!$A$3:$A$1002,$B$4,Aplicacoes!$C$3:$C$1002,"*"&$B11&"*")) | D11: =IFERROR($C11/$B$6,0)
A12: Crédito Privado | B12: CRED | C12: =IF($B12="",0,SUMIFS(Aplicacoes!$F$3:$F$1002,Aplicacoes!$A$3:$A$1002,$B$4,Aplicacoes!$C$3:$C$1002,"*"&$B12&"*")) | D12: =IFERROR($C12/$B$6,0)
A13: Letras (LCI/LCA) | B13: LETRAS | C13: =IF($B13="",0,SUMIFS(Aplicacoes!$F$3:$F$1002,Aplicacoes!$A$3:$A$1002,$B$4,Aplicacoes!$C$3:$C$1002,"*"&$B13&"*")) | D13: =IFERROR($C13/$B$6,0)
A14: CDB | B14: CDB | C14: =IF($B14="",0,SUMIFS(Aplicacoes!$F$3:$F$1002,Aplicacoes!$A$3:$A$1002,$B$4,Aplicacoes!$C$3:$C$1002,"*"&$B14&"*")) | D14: =IFERROR($C14/$B$6,0)
A15: LCA (emissor direto) | B15: LCA | C15: =IF($B15="",0,SUMIFS(Aplicacoes!$F$3:$F$1002,Aplicacoes!$A$3:$A$1002,$B$4,Aplicacoes!$C$3:$C$1002,"*"&$B15&"*")) | D15: =IFERROR($C15/$B$6,0)
A16: Tesouraria / Outros | B16: TESOURARIA | C16: =IF($B16="",0,SUMIFS(Aplicacoes!$F$3:$F$1002,Aplicacoes!$A$3:$A$1002,$B$4,Aplicacoes!$C$3:$C$1002,"*"&$B16&"*")) | D16: =IFERROR($C16/$B$6,0)
C17: =IF($B17="",0,SUMIFS(Aplicacoes!$F$3:$F$1002,Aplicacoes!$A$3:$A$1002,$B$4,Aplicacoes!$C$3:$C$1002,"*"&$B17&"*")) | D17: =IFERROR($C17/$B$6,0)
C18: =IF($B18="",0,SUMIFS(Aplicacoes!$F$3:$F$1002,Aplicacoes!$A$3:$A$1002,$B$4,Aplicacoes!$C$3:$C$1002,"*"&$B18&"*")) | D18: =IFERROR($C18/$B$6,0)
A19: TOTAL CLASSIFICADO | C19: =SUM(C11:C18) | D19: =SUM(D11:D18)
A20: Não classificado | C20: =$B$6-$C$19 | D20: =IFERROR($C20/$B$6,0)
A22: APLICAÇÕES DO CLIENTE
A23: Produto | B23: Subproduto | C23: Vencimento | D23: Saldo (R$) | E23: % carteira | F23: Idade
A24: =IFERROR(INDEX(Aplicacoes!$C$3:$C$1002,MATCH(1,Aplicacoes!$J$3:$J$1002,0)),"") | B24: =IFERROR(INDEX(Aplicacoes!$D$3:$D$1002,MATCH(1,Aplicacoes!$J$3:$J$1002,0)),"") | C24: =IFERROR(INDEX(Aplicacoes!$E$3:$E$1002,MATCH(1,Aplicacoes!$J$3:$J$1002,0)),"") | D24: =IFERROR(INDEX(Aplicacoes!$F$3:$F$1002,MATCH(1,Aplicacoes!$J$3:$J$1002,0)),"") | E24: =IFERROR(INDEX(Aplicacoes!$F$3:$F$1002,MATCH(1,Aplicacoes!$J$3:$J$1002,0))/$B$6,"") | F24: =IFERROR(INDEX(Aplicacoes!$G$3:$G$1002,MATCH(1,Aplicacoes!$J$3:$J$1002,0)),"")
A25: =IFERROR(INDEX(Aplicacoes!$C$3:$C$1002,MATCH(2,Aplicacoes!$J$3:$J$1002,0)),"") | B25: =IFERROR(INDEX(Aplicacoes!$D$3:$D$1002,MATCH(2,Aplicacoes!$J$3:$J$1002,0)),"") | C25: =IFERROR(INDEX(Aplicacoes!$E$3:$E$1002,MATCH(2,Aplicacoes!$J$3:$J$1002,0)),"") | D25: =IFERROR(INDEX(Aplicacoes!$F$3:$F$1002,MATCH(2,Aplicacoes!$J$3:$J$1002,0)),"") | E25: =IFERROR(INDEX(Aplicacoes!$F$3:$F$1002,MATCH(2,Aplicacoes!$J$3:$J$1002,0))/$B$6,"") | F25: =IFERROR(INDEX(Aplicacoes!$G$3:$G$1002,MATCH(2,Aplicacoes!$J$3:$J$1002,0)),"")
A26: =IFERROR(INDEX(Aplicacoes!$C$3:$C$1002,MATCH(3,Aplicacoes!$J$3:$J$1002,0)),"") | B26: =IFERROR(INDEX(Aplicacoes!$D$3:$D$1002,MATCH(3,Aplicacoes!$J$3:$J$1002,0)),"") | C26: =IFERROR(INDEX(Aplicacoes!$E$3:$E$1002,MATCH(3,Aplicacoes!$J$3:$J$1002,0)),"") | D26: =IFERROR(INDEX(Aplicacoes!$F$3:$F$1002,MATCH(3,Aplicacoes!$J$3:$J$1002,0)),"") | E26: =IFERROR(INDEX(Aplicacoes!$F$3:$F$1002,MATCH(3,Aplicacoes!$J$3:$J$1002,0))/$B$6,"") | F26: =IFERROR(INDEX(Aplicacoes!$G$3:$G$1002,MATCH(3,Aplicacoes!$J$3:$J$1002,0)),"")
A27: =IFERROR(INDEX(Aplicacoes!$C$3:$C$1002,MATCH(4,Aplicacoes!$J$3:$J$1002,0)),"") | B27: =IFERROR(INDEX(Aplicacoes!$D$3:$D$1002,MATCH(4,Aplicacoes!$J$3:$J$1002,0)),"") | C27: =IFERROR(INDEX(Aplicacoes!$E$3:$E$1002,MATCH(4,Aplicacoes!$J$3:$J$1002,0)),"") | D27: =IFERROR(INDEX(Aplicacoes!$F$3:$F$1002,MATCH(4,Aplicacoes!$J$3:$J$1002,0)),"") | E27: =IFERROR(INDEX(Aplicacoes!$F$3:$F$1002,MATCH(4,Aplicacoes!$J$3:$J$1002,0))/$B$6,"") | F27: =IFERROR(INDEX(Aplicacoes!$G$3:$G$1002,MATCH(4,Aplicacoes!$J$3:$J$1002,0)),"")
A28: =IFERROR(INDEX(Aplicacoes!$C$3:$C$1002,MATCH(5,Aplicacoes!$J$3:$J$1002,0)),"") | B28: =IFERROR(INDEX(Aplicacoes!$D$3:$D$1002,MATCH(5,Aplicacoes!$J$3:$J$1002,0)),"") | C28: =IFERROR(INDEX(Aplicacoes!$E$3:$E$1002,MATCH(5,Aplicacoes!$J$3:$J$1002,0)),"") | D28: =IFERROR(INDEX(Aplicacoes!$F$3:$F$1002,MATCH(5,Aplicacoes!$J$3:$J$1002,0)),"") | E28: =IFERROR(INDEX(Aplicacoes!$F$3:$F$1002,MATCH(5,Aplicacoes!$J$3:$J$1002,0))/$B$6,"") | F28: =IFERROR(INDEX(Aplicacoes!$G$3:$G$1002,MATCH(5,Aplicacoes!$J$3:$J$1002,0)),"")
A29: =IFERROR(INDEX(Aplicacoes!$C$3:$C$1002,MATCH(6,Aplicacoes!$J$3:$J$1002,0)),"") | B29: =IFERROR(INDEX(Aplicacoes!$D$3:$D$1002,MATCH(6,Aplicacoes!$J$3:$J$1002,0)),"") | C29: =IFERROR(INDEX(Aplicacoes!$E$3:$E$1002,MATCH(6,Aplicacoes!$J$3:$J$1002,0)),"") | D29: =IFERROR(INDEX(Aplicacoes!$F$3:$F$1002,MATCH(6,Aplicacoes!$J$3:$J$1002,0)),"") | E29: =IFERROR(INDEX(Aplicacoes!$F$3:$F$1002,MATCH(6,Aplicacoes!$J$3:$J$1002,0))/$B$6,"") | F29: =IFERROR(INDEX(Aplicacoes!$G$3:$G$1002,MATCH(6,Aplicacoes!$J$3:$J$1002,0)),"")
A30: =IFERROR(INDEX(Aplicacoes!$C$3:$C$1002,MATCH(7,Aplicacoes!$J$3:$J$1002,0)),"") | B30: =IFERROR(INDEX(Aplicacoes!$D$3:$D$1002,MATCH(7,Aplicacoes!$J$3:$J$1002,0)),"") | C30: =IFERROR(INDEX(Aplicacoes!$E$3:$E$1002,MATCH(7,Aplicacoes!$J$3:$J$1002,0)),"") | D30: =IFERROR(INDEX(Aplicacoes!$F$3:$F$1002,MATCH(7,Aplicacoes!$J$3:$J$1002,0)),"") | E30: =IFERROR(INDEX(Aplicacoes!$F$3:$F$1002,MATCH(7,Aplicacoes!$J$3:$J$1002,0))/$B$6,"") | F30: =IFERROR(INDEX(Aplicacoes!$G$3:$G$1002,MATCH(7,Aplicacoes!$J$3:$J$1002,0)),"")
A31: =IFERROR(INDEX(Aplicacoes!$C$3:$C$1002,MATCH(8,Aplicacoes!$J$3:$J$1002,0)),"") | B31: =IFERROR(INDEX(Aplicacoes!$D$3:$D$1002,MATCH(8,Aplicacoes!$J$3:$J$1002,0)),"") | C31: =IFERROR(INDEX(Aplicacoes!$E$3:$E$1002,MATCH(8,Aplicacoes!$J$3:$J$1002,0)),"") | D31: =IFERROR(INDEX(Aplicacoes!$F$3:$F$1002,MATCH(8,Aplicacoes!$J$3:$J$1002,0)),"") | E31: =IFERROR(INDEX(Aplicacoes!$F$3:$F$1002,MATCH(8,Aplicacoes!$J$3:$J$1002,0))/$B$6,"") | F31: =IFERROR(INDEX(Aplicacoes!$G$3:$G$1002,MATCH(8,Aplicacoes!$J$3:$J$1002,0)),"")
A32: =IFERROR(INDEX(Aplicacoes!$C$3:$C$1002,MATCH(9,Aplicacoes!$J$3:$J$1002,0)),"") | B32: =IFERROR(INDEX(Aplicacoes!$D$3:$D$1002,MATCH(9,Aplicacoes!$J$3:$J$1002,0)),"") | C32: =IFERROR(INDEX(Aplicacoes!$E$3:$E$1002,MATCH(9,Aplicacoes!$J$3:$J$1002,0)),"") | D32: =IFERROR(INDEX(Aplicacoes!$F$3:$F$1002,MATCH(9,Aplicacoes!$J$3:$J$1002,0)),"") | E32: =IFERROR(INDEX(Aplicacoes!$F$3:$F$1002,MATCH(9,Aplicacoes!$J$3:$J$1002,0))/$B$6,"") | F32: =IFERROR(INDEX(Aplicacoes!$G$3:$G$1002,MATCH(9,Aplicacoes!$J$3:$J$1002,0)),"")
A33: =IFERROR(INDEX(Aplicacoes!$C$3:$C$1002,MATCH(10,Aplicacoes!$J$3:$J$1002,0)),"") | B33: =IFERROR(INDEX(Aplicacoes!$D$3:$D$1002,MATCH(10,Aplicacoes!$J$3:$J$1002,0)),"") | C33: =IFERROR(INDEX(Aplicacoes!$E$3:$E$1002,MATCH(10,Aplicacoes!$J$3:$J$1002,0)),"") | D33: =IFERROR(INDEX(Aplicacoes!$F$3:$F$1002,MATCH(10,Aplicacoes!$J$3:$J$1002,0)),"") | E33: =IFERROR(INDEX(Aplicacoes!$F$3:$F$1002,MATCH(10,Aplicacoes!$J$3:$J$1002,0))/$B$6,"") | F33: =IFERROR(INDEX(Aplicacoes!$G$3:$G$1002,MATCH(10,Aplicacoes!$J$3:$J$1002,0)),"")
A34: =IFERROR(INDEX(Aplicacoes!$C$3:$C$1002,MATCH(11,Aplicacoes!$J$3:$J$1002,0)),"") | B34: =IFERROR(INDEX(Aplicacoes!$D$3:$D$1002,MATCH(11,Aplicacoes!$J$3:$J$1002,0)),"") | C34: =IFERROR(INDEX(Aplicacoes!$E$3:$E$1002,MATCH(11,Aplicacoes!$J$3:$J$1002,0)),"") | D34: =IFERROR(INDEX(Aplicacoes!$F$3:$F$1002,MATCH(11,Aplicacoes!$J$3:$J$1002,0)),"") | E34: =IFERROR(INDEX(Aplicacoes!$F$3:$F$1002,MATCH(11,Aplicacoes!$J$3:$J$1002,0))/$B$6,"") | F34: =IFERROR(INDEX(Aplicacoes!$G$3:$G$1002,MATCH(11,Aplicacoes!$J$3:$J$1002,0)),"")
A35: =IFERROR(INDEX(Aplicacoes!$C$3:$C$1002,MATCH(12,Aplicacoes!$J$3:$J$1002,0)),"") | B35: =IFERROR(INDEX(Aplicacoes!$D$3:$D$1002,MATCH(12,Aplicacoes!$J$3:$J$1002,0)),"") | C35: =IFERROR(INDEX(Aplicacoes!$E$3:$E$1002,MATCH(12,Aplicacoes!$J$3:$J$1002,0)),"") | D35: =IFERROR(INDEX(Aplicacoes!$F$3:$F$1002,MATCH(12,Aplicacoes!$J$3:$J$1002,0)),"") | E35: =IFERROR(INDEX(Aplicacoes!$F$3:$F$1002,MATCH(12,Aplicacoes!$J$3:$J$1002,0))/$B$6,"") | F35: =IFERROR(INDEX(Aplicacoes!$G$3:$G$1002,MATCH(12,Aplicacoes!$J$3:$J$1002,0)),"")
A36: =IFERROR(INDEX(Aplicacoes!$C$3:$C$1002,MATCH(13,Aplicacoes!$J$3:$J$1002,0)),"") | B36: =IFERROR(INDEX(Aplicacoes!$D$3:$D$1002,MATCH(13,Aplicacoes!$J$3:$J$1002,0)),"") | C36: =IFERROR(INDEX(Aplicacoes!$E$3:$E$1002,MATCH(13,Aplicacoes!$J$3:$J$1002,0)),"") | D36: =IFERROR(INDEX(Aplicacoes!$F$3:$F$1002,MATCH(13,Aplicacoes!$J$3:$J$1002,0)),"") | E36: =IFERROR(INDEX(Aplicacoes!$F$3:$F$1002,MATCH(13,Aplicacoes!$J$3:$J$1002,0))/$B$6,"") | F36: =IFERROR(INDEX(Aplicacoes!$G$3:$G$1002,MATCH(13,Aplicacoes!$J$3:$J$1002,0)),"")
A37: =IFERROR(INDEX(Aplicacoes!$C$3:$C$1002,MATCH(14,Aplicacoes!$J$3:$J$1002,0)),"") | B37: =IFERROR(INDEX(Aplicacoes!$D$3:$D$1002,MATCH(14,Aplicacoes!$J$3:$J$1002,0)),"") | C37: =IFERROR(INDEX(Aplicacoes!$E$3:$E$1002,MATCH(14,Aplicacoes!$J$3:$J$1002,0)),"") | D37: =IFERROR(INDEX(Aplicacoes!$F$3:$F$1002,MATCH(14,Aplicacoes!$J$3:$J$1002,0)),"") | E37: =IFERROR(INDEX(Aplicacoes!$F$3:$F$1002,MATCH(14,Aplicacoes!$J$3:$J$1002,0))/$B$6,"") | F37: =IFERROR(INDEX(Aplicacoes!$G$3:$G$1002,MATCH(14,Aplicacoes!$J$3:$J$1002,0)),"")
A38: =IFERROR(INDEX(Aplicacoes!$C$3:$C$1002,MATCH(15,Aplicacoes!$J$3:$J$1002,0)),"") | B38: =IFERROR(INDEX(Aplicacoes!$D$3:$D$1002,MATCH(15,Aplicacoes!$J$3:$J$1002,0)),"") | C38: =IFERROR(INDEX(Aplicacoes!$E$3:$E$1002,MATCH(15,Aplicacoes!$J$3:$J$1002,0)),"") | D38: =IFERROR(INDEX(Aplicacoes!$F$3:$F$1002,MATCH(15,Aplicacoes!$J$3:$J$1002,0)),"") | E38: =IFERROR(INDEX(Aplicacoes!$F$3:$F$1002,MATCH(15,Aplicacoes!$J$3:$J$1002,0))/$B$6,"") | F38: =IFERROR(INDEX(Aplicacoes!$G$3:$G$1002,MATCH(15,Aplicacoes!$J$3:$J$1002,0)),"")
A39: =IFERROR(INDEX(Aplicacoes!$C$3:$C$1002,MATCH(16,Aplicacoes!$J$3:$J$1002,0)),"") | B39: =IFERROR(INDEX(Aplicacoes!$D$3:$D$1002,MATCH(16,Aplicacoes!$J$3:$J$1002,0)),"") | C39: =IFERROR(INDEX(Aplicacoes!$E$3:$E$1002,MATCH(16,Aplicacoes!$J$3:$J$1002,0)),"") | D39: =IFERROR(INDEX(Aplicacoes!$F$3:$F$1002,MATCH(16,Aplicacoes!$J$3:$J$1002,0)),"") | E39: =IFERROR(INDEX(Aplicacoes!$F$3:$F$1002,MATCH(16,Aplicacoes!$J$3:$J$1002,0))/$B$6,"") | F39: =IFERROR(INDEX(Aplicacoes!$G$3:$G$1002,MATCH(16,Aplicacoes!$J$3:$J$1002,0)),"")
A40: =IFERROR(INDEX(Aplicacoes!$C$3:$C$1002,MATCH(17,Aplicacoes!$J$3:$J$1002,0)),"") | B40: =IFERROR(INDEX(Aplicacoes!$D$3:$D$1002,MATCH(17,Aplicacoes!$J$3:$J$1002,0)),"") | C40: =IFERROR(INDEX(Aplicacoes!$E$3:$E$1002,MATCH(17,Aplicacoes!$J$3:$J$1002,0)),"") | D40: =IFERROR(INDEX(Aplicacoes!$F$3:$F$1002,MATCH(17,Aplicacoes!$J$3:$J$1002,0)),"") | E40: =IFERROR(INDEX(Aplicacoes!$F$3:$F$1002,MATCH(17,Aplicacoes!$J$3:$J$1002,0))/$B$6,"") | F40: =IFERROR(INDEX(Aplicacoes!$G$3:$G$1002,MATCH(17,Aplicacoes!$J$3:$J$1002,0)),"")
A41: =IFERROR(INDEX(Aplicacoes!$C$3:$C$1002,MATCH(18,Aplicacoes!$J$3:$J$1002,0)),"") | B41: =IFERROR(INDEX(Aplicacoes!$D$3:$D$1002,MATCH(18,Aplicacoes!$J$3:$J$1002,0)),"") | C41: =IFERROR(INDEX(Aplicacoes!$E$3:$E$1002,MATCH(18,Aplicacoes!$J$3:$J$1002,0)),"") | D41: =IFERROR(INDEX(Aplicacoes!$F$3:$F$1002,MATCH(18,Aplicacoes!$J$3:$J$1002,0)),"") | E41: =IFERROR(INDEX(Aplicacoes!$F$3:$F$1002,MATCH(18,Aplicacoes!$J$3:$J$1002,0))/$B$6,"") | F41: =IFERROR(INDEX(Aplicacoes!$G$3:$G$1002,MATCH(18,Aplicacoes!$J$3:$J$1002,0)),"")
A42: =IFERROR(INDEX(Aplicacoes!$C$3:$C$1002,MATCH(19,Aplicacoes!$J$3:$J$1002,0)),"") | B42: =IFERROR(INDEX(Aplicacoes!$D$3:$D$1002,MATCH(19,Aplicacoes!$J$3:$J$1002,0)),"") | C42: =IFERROR(INDEX(Aplicacoes!$E$3:$E$1002,MATCH(19,Aplicacoes!$J$3:$J$1002,0)),"") | D42: =IFERROR(INDEX(Aplicacoes!$F$3:$F$1002,MATCH(19,Aplicacoes!$J$3:$J$1002,0)),"") | E42: =IFERROR(INDEX(Aplicacoes!$F$3:$F$1002,MATCH(19,Aplicacoes!$J$3:$J$1002,0))/$B$6,"") | F42: =IFERROR(INDEX(Aplicacoes!$G$3:$G$1002,MATCH(19,Aplicacoes!$J$3:$J$1002,0)),"")
A43: =IFERROR(INDEX(Aplicacoes!$C$3:$C$1002,MATCH(20,Aplicacoes!$J$3:$J$1002,0)),"") | B43: =IFERROR(INDEX(Aplicacoes!$D$3:$D$1002,MATCH(20,Aplicacoes!$J$3:$J$1002,0)),"") | C43: =IFERROR(INDEX(Aplicacoes!$E$3:$E$1002,MATCH(20,Aplicacoes!$J$3:$J$1002,0)),"") | D43: =IFERROR(INDEX(Aplicacoes!$F$3:$F$1002,MATCH(20,Aplicacoes!$J$3:$J$1002,0)),"") | E43: =IFERROR(INDEX(Aplicacoes!$F$3:$F$1002,MATCH(20,Aplicacoes!$J$3:$J$1002,0))/$B$6,"") | F43: =IFERROR(INDEX(Aplicacoes!$G$3:$G$1002,MATCH(20,Aplicacoes!$J$3:$J$1002,0)),"")
...

Sheet Carteira Sugerida
A1: PROPOSTA DE CARTEIRA
A3: Cliente: | B3: ='Carteira do Cliente'!B3 | H3: PATRIMÔNIO PROPOSTO
A4: Patrimônio Atual: | B4: ='Carteira do Cliente'!B6 | H4: =SUM(E8:E32)
A6: CARTEIRA RECOMENDADA
A7: Classe | B7: Ativo sugerido | C7: Carência (dias corridos) | D7: Liquidez (D + dias) | E7: Valor (R$) | F7: % | Q7: Classe | R7: Valor | S7: D+ | T7: Valor
F8: =IFERROR($E8/SUM($E$8:$E$32),"") | Q8: ='Carteira do Cliente'!A11 | R8: =IF($Q8="",0,SUMIFS($E$8:$E$32,$A$8:$A$32,$Q8)) | S8: 0 | T8: =SUMIFS($E$8:$E$32,$D$8:$D$32,$S8)
F9: =IFERROR($E9/SUM($E$8:$E$32),"") | Q9: ='Carteira do Cliente'!A12 | R9: =IF($Q9="",0,SUMIFS($E$8:$E$32,$A$8:$A$32,$Q9)) | S9: 1 | T9: =SUMIFS($E$8:$E$32,$D$8:$D$32,$S9)
F10: =IFERROR($E10/SUM($E$8:$E$32),"") | Q10: ='Carteira do Cliente'!A13 | R10: =IF($Q10="",0,SUMIFS($E$8:$E$32,$A$8:$A$32,$Q10)) | S10: 10 | T10: =SUMIFS($E$8:$E$32,$D$8:$D$32,$S10)
F11: =IFERROR($E11/SUM($E$8:$E$32),"") | Q11: ='Carteira do Cliente'!A14 | R11: =IF($Q11="",0,SUMIFS($E$8:$E$32,$A$8:$A$32,$Q11)) | S11: 30 | T11: =SUMIFS($E$8:$E$32,$D$8:$D$32,$S11)
F12: =IFERROR($E12/SUM($E$8:$E$32),"") | Q12: ='Carteira do Cliente'!A15 | R12: =IF($Q12="",0,SUMIFS($E$8:$E$32,$A$8:$A$32,$Q12)) | S12: 45 | T12: =SUMIFS($E$8:$E$32,$D$8:$D$32,$S12)
F13: =IFERROR($E13/SUM($E$8:$E$32),"") | Q13: ='Carteira do Cliente'!A16 | R13: =IF($Q13="",0,SUMIFS($E$8:$E$32,$A$8:$A$32,$Q13)) | S13: 90 | T13: =SUMIFS($E$8:$E$32,$D$8:$D$32,$S13)
F14: =IFERROR($E14/SUM($E$8:$E$32),"") | Q14: ='Carteira do Cliente'!A17 | R14: =IF($Q14="",0,SUMIFS($E$8:$E$32,$A$8:$A$32,$Q14)) | S14: 180 | T14: =SUMIFS($E$8:$E$32,$D$8:$D$32,$S14)
F15: =IFERROR($E15/SUM($E$8:$E$32),"") | Q15: ='Carteira do Cliente'!A18 | R15: =IF($Q15="",0,SUMIFS($E$8:$E$32,$A$8:$A$32,$Q15)) | S15: 270 | T15: =SUMIFS($E$8:$E$32,$D$8:$D$32,$S15)
F16: =IFERROR($E16/SUM($E$8:$E$32),"") | S16: 365 | T16: =SUMIFS($E$8:$E$32,$D$8:$D$32,$S16)
F17: =IFERROR($E17/SUM($E$8:$E$32),"") | S17: 720 | T17: =SUMIFS($E$8:$E$32,$D$8:$D$32,$S17)
F18: =IFERROR($E18/SUM($E$8:$E$32),"") | S18: 1800 | T18: =SUMIFS($E$8:$E$32,$D$8:$D$32,$S18)
F19: =IFERROR($E19/SUM($E$8:$E$32),"")
F20: =IFERROR($E20/SUM($E$8:$E$32),"")
F21: =IFERROR($E21/SUM($E$8:$E$32),"")
F22: =IFERROR($E22/SUM($E$8:$E$32),"")
F23: =IFERROR($E23/SUM($E$8:$E$32),"")
F24: =IFERROR($E24/SUM($E$8:$E$32),"")
F25: =IFERROR($E25/SUM($E$8:$E$32),"")
F26: =IFERROR($E26/SUM($E$8:$E$32),"")
F27: =IFERROR($E27/SUM($E$8:$E$32),"")
F28: =IFERROR($E28/SUM($E$8:$E$32),"")
F29: =IFERROR($E29/SUM($E$8:$E$32),"")
F30: =IFERROR($E30/SUM($E$8:$E$32),"")
... F32: =IFERROR($E32/SUM($E$8:$E$32),"")
A33: TOTAL | E33: =SUM(E8:E32) | F33: =SUM(F8:F32)
A37: OTIMIZAÇÕES REALIZADAS
A44: RACIONAL POR MOVIMENTAÇÃO
A45: Ativo | B45: Racional (objetivo e justificativa)
A57: COMPARATIVO: ATUAL x SUGERIDA
A58: Classe | B58: % Atual | C58: % Sugerido | D58: Saldo Atual (R$) | E58: Valor Sugerido (R$) | F58: Diferença (R$) | G58: Ação
A59: ='Carteira do Cliente'!A11 | B59: ='Carteira do Cliente'!D11 | C59: =IFERROR($E59/SUM($E$8:$E$32),0) | D59: ='Carteira do Cliente'!C11 | E59: =SUMIFS($E$8:$E$32,$A$8:$A$32,$A59) | F59: =$E59-$D59 | G59: =IF(AND($D59=0,$E59=0),"",IF(ROUND($F59,2)>0,"Aumentar",IF(ROUND($F59,2)<0,"Reduzir","Manter")))
A60: ='Carteira do Cliente'!A12 | B60: ='Carteira do Cliente'!D12 | C60: =IFERROR($E60/SUM($E$8:$E$32),0) | D60: ='Carteira do Cliente'!C12 | E60: =SUMIFS($E$8:$E$32,$A$8:$A$32,$A60) | F60: =$E60-$D60 | G60: =IF(AND($D60=0,$E60=0),"",IF(ROUND($F60,2)>0,"Aumentar",IF(ROUND($F60,2)<0,"Reduzir","Manter")))
A61: ='Carteira do Cliente'!A13 | B61: ='Carteira do Cliente'!D13 | C61: =IFERROR($E61/SUM($E$8:$E$32),0) | D61: ='Carteira do Cliente'!C13 | E61: =SUMIFS($E$8:$E$32,$A$8:$A$32,$A61) | F61: =$E61-$D61 | G61: =IF(AND($D61=0,$E61=0),"",IF(ROUND($F61,2)>0,"Aumentar",IF(ROUND($F61,2)<0,"Reduzir","Manter")))
A62: ='Carteira do Cliente'!A14 | B62: ='Carteira do Cliente'!D14 | C62: =IFERROR($E62/SUM($E$8:$E$32),0) | D62: ='Carteira do Cliente'!C14 | E62: =SUMIFS($E$8:$E$32,$A$8:$A$32,$A62) | F62: =$E62-$D62 | G62: =IF(AND($D62=0,$E62=0),"",IF(ROUND($F62,2)>0,"Aumentar",IF(ROUND($F62,2)<0,"Reduzir","Manter")))
A63: ='Carteira do Cliente'!A15 | B63: ='Carteira do Cliente'!D15 | C63: =IFERROR($E63/SUM($E$8:$E$32),0) | D63: ='Carteira do Cliente'!C15 | E63: =SUMIFS($E$8:$E$32,$A$8:$A$32,$A63) | F63: =$E63-$D63 | G63: =IF(AND($D63=0,$E63=0),"",IF(ROUND($F63,2)>0,"Aumentar",IF(ROUND($F63,2)<0,"Reduzir","Manter")))
...

Sheet Planejamento
A1: PLANEJAMENTO FINANCEIRO & APOSENTADORIA
A3: Cliente: | B3: ='Carteira do Cliente'!B3
A5: INFORMAÇÕES GERAIS E PATRIMÔNIO ATUAL | D5: INFLAÇÃO, CDI, ALÍQUOTA IR E TAXA NOMINAL
A6: Idade atual (anos) | B6: 51 | D6: Inflação anual projetada | E6: 0.04
A7: Idade de aposentadoria (anos) | B7: 64 | D7: Alíquota de IR (sobre rendimentos) | E7: 0.15
A8: Expectativa de vida (anos) | B8: 90 | D8: Taxa CDI anual | E8: 0.1065
A9: Horizonte de produção/acumulação (anos) | B9: =B7-B6 | D9: % do CDI esperado (rentabilidade) | E9: 0.72
A10: Patrimônio líquido disponível (R$) | B10: 0 | D10: Taxa nominal anual bruta (calc) | E10: =E8*E9
A11: Aplicação mensal (Prev + Meta) (R$) | B11: 0 | D11: Taxa nominal anual líquida (calc) | E11: =E10*(1-E7)
A13: PREMISSAS DE APOSENTADORIA | D13: TAXA DE JUROS REAL
A14: Renda desejada na aposentadoria (R$ / mês) | B14: 0 | D14: Taxa real anual bruta | E14: =(1+E10)/(1+E6)-1
A15: Renda projetada do INSS (R$ / mês) | B15: 0 | D15: Taxa real anual líquida | E15: =(1+E11)/(1+E6)-1
A16: Outras fontes de renda (R$ / mês) | B16: 0 | D16: Taxa real anual líquida pós-aposentadoria | E16: 0.03
A17: Renda a sustentar pelo patrimônio (R$ / mês) | B17: =MAX(0,B14-B15-B16) | D17: Taxa real mensal líquida pós-aposentadoria | E17: =(1+E16)^(1/12)-1
A18: Renda a sustentar pelo patrimônio (R$ / ano) | B18: =B17*12
A20: APOSENTADORIA — VIVER DE RENDA (preservando) | D20: APOSENTADORIA — CONSUMO COM SUCESSÃO
A21: Patrimônio necessário na aposentadoria | B21: =IFERROR(B18/E16,0) | D21: Patrimônio de sucessão desejado (R$) | E21: 0
A22: Parcela mensal necessária a aplicar | B22: =IFERROR(-PMT(E17,B9*12,-B10,B21),0) | D22: Patrimônio necessário na aposentadoria | E22: =IFERROR(PV(E16,B8-B7,-B18,-E21),0)
D23: Parcela mensal necessária a aplicar | E23: =IFERROR(-PMT(E17,B9*12,-B10,E22),0)
A25: OBJETIVOS DE VIDA (1-6 anos)
A26: Projeto | B26: Valor hoje (R$) | D26: Acumulação projetada (R$) | E26: Anos
A27: Projetos 1-2 anos | B27: 0 | D27: =B27*(1+E10)^E27 | E27: 2
A28: Projetos 3-4 anos | B28: 0 | D28: =B28*(1+E10)^E28 | E28: 4
A29: Projetos 5-6 anos | B29: 0 | D29: =B29*(1+E10)^E29 | E29: 6
A30: Total de Projetos e Acumulação | B30: =SUM(B27:B29) | D30: =SUM(D27:D29)
G33: PROJEÇÃO PATRIMONIAL (em R$ reais de hoje)
G34: Ano | H34: Idade | I34: Saldo Real | J34: Viver de Renda
G35: 0 | H35: =B6+G35 | I35: =B10 | J35: =IF(H35<B7,NA(),B21)
G36: 1 | H36: =B6+G36 | I36: =IF(H36<=B7,I35*(1+E15)+B11*12,MAX(0,I35*(1+E16)-B18)) | J36: =IF(H36<B7,NA(),B21)
G37: 2 | H37: =B6+G37 | I37: =IF(H37<=B7,I36*(1+E15)+B11*12,MAX(0,I36*(1+E16)-B18)) | J37: =IF(H37<B7,NA(),B21)
G38: 3 | H38: =B6+G38 | I38: =IF(H38<=B7,I37*(1+E15)+B11*12,MAX(0,I37*(1+E16)-B18)) | J38: =IF(H38<B7,NA(),B21)
G39: 4 | H39: =B6+G39 | I39: =IF(H39<=B7,I38*(1+E15)+B11*12,MAX(0,I38*(1+E16)-B18)) | J39: =IF(H39<B7,NA(),B21)
G40: 5 | H40: =B6+G40 | I40: =IF(H40<=B7,I39*(1+E15)+B11*12,MAX(0,I39*(1+E16)-B18)) | J40: =IF(H40<B7,NA(),B21)
G41: 6 | H41: =B6+G41 | I41: =IF(H41<=B7,I40*(1+E15)+B11*12,MAX(0,I40*(1+E16)-B18)) | J41: =IF(H41<B7,NA(),B21)
G42: 7 | H42: =B6+G42 | I42: =IF(H42<=B7,I41*(1+E15)+B11*12,MAX(0,I41*(1+E16)-B18)) | J42: =IF(H42<B7,NA(),B21)
G43: 8 | H43: =B6+G43 | I43: =IF(H43<=B7,I42*(1+E15)+B11*12,MAX(0,I42*(1+E16)-B18)) | J43: =IF(H43<B7,NA(),B21)
G44: 9 | H44: =B6+G44 | I44: =IF(H44<=B7,I43*(1+E15)+B11*12,MAX(0,I43*(1+E16)-B18)) | J44: =IF(H44<B7,NA(),B21)
G45: 10 | H45: =B6+G45 | I45: =IF(H45<=B7,I44*(1+E15)+B11*12,MAX(0,I44*(1+E16)-B18)) | J45: =IF(H45<B7,NA(),B21)
G46: 11 | H46: =B6+G46 | I46: =IF(H46<=B7,I45*(1+E15)+B11*12,MAX(0,I45*(1+E16)-B18)) | J46: =IF(H46<B7,NA(),B21)
G47: 12 | H47: =B6+G47 | I47: =IF(H47<=B7,I46*(1+E15)+B11*12,MAX(0,I46*(1+E16)-B18)) | J47: =IF(H47<B7,NA(),B21)
...

Sheet Tabela Periódica
A1: TABELA PERIÓDICA DOS INVESTIMENTOS — RETORNO ANUAL
A3: Índice / Classe | B3: 2017 | C3: 2018 | D3: 2019 | E3: 2020 | F3: 2021 | G3: 2022 | H3: 2023 | I3: 2024 | J3: Acumulado
A4: S&P 500 | J4: =IFERROR(PRODUCT(IF(ISNUMBER(B4:I4),1+B4:I4,1))-1,"")
A5: Euro Stoxx 50 | J5: =IFERROR(PRODUCT(IF(ISNUMBER(B5:I5),1+B5:I5,1))-1,"")
A6: Ibovespa | J6: =IFERROR(PRODUCT(IF(ISNUMBER(B6:I6),1+B6:I6,1))-1,"")
A7: IFIX | J7: =IFERROR(PRODUCT(IF(ISNUMBER(B7:I7),1+B7:I7,1))-1,"")
A8: IMA-B | J8: =IFERROR(PRODUCT(IF(ISNUMBER(B8:I8),1+B8:I8,1))-1,"")
A9: IRF-M | J9: =IFERROR(PRODUCT(IF(ISNUMBER(B9:I9),1+B9:I9,1))-1,"")
A10: IHFA | J10: =IFERROR(PRODUCT(IF(ISNUMBER(B10:I10),1+B10:I10,1))-1,"")
A11: CDI | J11: =IFERROR(PRODUCT(IF(ISNUMBER(B11:I11),1+B11:I11,1))-1,"")
A12: Dólar | J12: =IFERROR(PRODUCT(IF(ISNUMBER(B12:I12),1+B12:I12,1))-1,"")
A13: Inflação | J13: =IFERROR(PRODUCT(IF(ISNUMBER(B13:I13),1+B13:I13,1))-1,"")
A16: Preencha os retornos anuais (em %) de cada índice/classe. A coluna Acumulado é calculada automaticamente; a cor destaca os melhores (verde) e piores (vermelho) de cada ano.

Sheet Instruções
A1: COMO USAR ESTA PLANILHA
A3: 1. Aba 'Clientes': cadastre cada cliente uma única vez — Penumper, Nome e CPF. O Penumper é a chave que liga tudo; pode ter letras (ex.: 1297217A), por isso a coluna é formatada como texto.
A4: Penumper ou CPF repetidos ficam destacados em vermelho.
A6: 2. Aba 'Aplicacoes': cole aqui a posição vinda do sistema — Penumper, Mês, Produto, Subproduto, Vencimento, Saldo Ponta e Idade.
A7: As colunas Nome e CPF se preenchem sozinhas por PROCV usando o Penumper. Se aparecer 'NÃO CADASTRADO', falta cadastrar o cliente na aba 'Clientes'.
A8: Cada linha é um investimento (um produto/subproduto com saldo).
A10: 3. Aba 'Carteira do Cliente': escolha o cliente no menu suspenso. A planilha mostra o patrimônio total, a alocação por classe (com gráfico) e a lista das aplicações daquele cliente.
A11: A linha 'Não classificado' indica saldo cujo Produto não casou com nenhum filtro — ajuste os filtros da coluna B se isso acontecer.
A13: 4. Classes: na aba 'Carteira do Cliente' a coluna 'Filtro (contém)' define como cada classe é somada. Ex.: o filtro FUNDOS soma todo Produto que contenha 'FUNDOS'. Edite rótulos e filtros à vontade.
A15: 5. Aba 'Carteira Sugerida' (proposta): monte a carteira recomendada — Classe, Ativo sugerido, Carência (dias), Liquidez (dias) e Valor. O banner 'Patrimônio Proposto' soma sozinho e os dois gráficos (composição por classe e distribuição de liquidez) se atualizam.
A16: Logo abaixo há campos livres para você descrever as Otimizações Realizadas e o Racional por movimentação (objetivo, justificativa).
A17: O Comparativo no fim mostra, classe a classe, o % atual x o % sugerido e quanto Aumentar ou Reduzir.
... A23: Observação: a planilha trabalha com a posição atual (foto). Para acrescentar uma nova posição, basta colar mais linhas na aba 'Aplicacoes' — as fórmulas se estendem automaticamente.
